Workbook

Sheet PDF정보
A1: 코드 | B1: 273130 | O1: 코드 | P1: 363570 | AC1: 코드 | AD1: 439870 | AQ1: 코드 | AR1: 438570 | BE1: 코드 | BF1: 438560 | BS1: 코드 | BT1: 436140 | CG1: 코드 | CH1: 469830 | CU1: 코드 | CV1: 0016X0 | DI1: 코드 | DJ1: 385540 | DW1: 코드 | DX1: 0141T0 | EK1: 코드 | EL1: 438330
A2: 조회건수 | B2: 1000 | O2: 조회건수 | P2: 1000 | AC2: 조회건수 | AD2: 1000 | AQ2: 조회건수 | AR2: 1000 | BE2: 조회건수 | BF2: 1000 | BS2: 조회건수 | BT2: 1000 | CG2: 조회건수 | CH2: 1000 | CU2: 조회건수 | CV2: 1000 | DI2: 조회건수 | DJ2: 1000 | DW2: 조회건수 | DX2: 1000 | EK2: 조회건수 | EL2: 1000
A3: 일자 | B3: =TODAY() -> 46316 | O3: 일자 | P3: =TODAY() -> 46316 | AC3: 일자 | AD3: =TODAY() -> 46316 | AQ3: 일자 | AR3: =TODAY() -> 46316 | BE3: 일자 | BF3: =TODAY() -> 46316 | BS3: 일자 | BT3: =TODAY() -> 46316 | CG3: 일자 | CH3: =TODAY() -> 46316 | CU3: 일자 | CV3: =TODAY() -> 46316 | DI3: 일자 | DJ3: =TODAY() -> 46316 | DW3: 일자 | DX3: =TODAY() -> 46316 | EK3: 일자 | EL3: =TODAY() -> 46316
A4: 조회기준 | B4: - | O4: 조회기준 | P4: - | AC4: 조회기준 | AD4: - | AQ4: 조회기준 | AR4: - | BE4: 조회기준 | BF4: - | BS4: 조회기준 | BT4: - | CG4: 조회기준 | CH4: - | CU4: 조회기준 | CV4: - | DI4: 조회기준 | DJ4: - | DW4: 조회기준 | DX4: - | EK4: 조회기준 | EL4: -
A5: 정렬기준 | B5: ETF비중 | O5: 정렬기준 | P5: ETF비중 | AC5: 정렬기준 | AD5: ETF비중 | AQ5: 정렬기준 | AR5: ETF비중 | BE5: 정렬기준 | BF5: ETF비중 | BS5: 정렬기준 | BT5: ETF비중 | CG5: 정렬기준 | CH5: ETF비중 | CU5: 정렬기준 | CV5: ETF비중 | DI5: 정렬기준 | DJ5: ETF비중 | DW5: 정렬기준 | DX5: ETF비중 | EK5: 정렬기준 | EL5: ETF비중
A6: 정렬 | B6: D | O6: 정렬 | P6: D | AC6: 정렬 | AD6: D | AQ6: 정렬 | AR6: D | BE6: 정렬 | BF6: D | BS6: 정렬 | BT6: D | CG6: 정렬 | CH6: D | CU6: 정렬 | CV6: D | DI6: 정렬 | DJ6: D | DW6: 정렬 | DX6: D | EK6: 정렬 | EL6: D
A7: =_xll.IMDT("ETP구성",B1,A8:J8,B2,B3,B4,B5,"sort="&B6&",DtFmt=1,TmFmt=1,Pos=20,Orient=V,Title=KODEX 종합채권(AA-이상)액티브") -> KODEX 종합채권(AA-이상)액티브 | O7: =_xll.IMDT("ETP구성",P1,O8:X8,P2,P3,P4,P5,"sort="&P6&",DtFmt=1,TmFmt=1,Pos=20,Orient=V,Title=KODEX 장기종합채권(AA-이상)액티브") -> KODEX 장기종합채권(AA-이상)액티브 | AC7: =_xll.IMDT("ETP구성",AD1,AC8:AL8,AD2,AD3,AD4,AD5,"sort="&AD6&",DtFmt=1,TmFmt=1,Pos=20,Orient=V,Title=KODEX 국고채30년액티브") -> KODEX 국고채30년액티브 | AQ7: =_xll.IMDT("ETP구성",AR1,AQ8:AZ8,AR2,AR3,AR4,AR5,"sort="&AR6&",DtFmt=1,TmFmt=1,Pos=20,Orient=V,Title=SOL 국고채10년") -> SOL 국고채10년 | BE7: =_xll.IMDT("ETP구성",BF1,BE8:BN8,BF2,BF3,BF4,BF5,"sort="&BF6&",DtFmt=1,TmFmt=1,Pos=20,Orient=V,Title=SOL 국고채3년") -> SOL 국고채3년 | BS7: =_xll.IMDT("ETP구성",BT1,BS8:CB8,BT2,BT3,BT4,BT5,"sort="&BT6&",DtFmt=1,TmFmt=1,Pos=20,Orient=V,Title=SOL 종합채권(AA-이상)액티브") -> SOL 종합채권(AA-이상)액티브 | CG7: =_xll.IMDT("ETP구성",CH1,CG8:CP8,CH2,CH3,CH4,CH5,"sort="&CH6&",DtFmt=1,TmFmt=1,Pos=20,Orient=V,Title=SOL 초단기채권액티브") -> SOL 초단기채권액티브 | CU7: =_xll.IMDT("ETP구성",CV1,CU8:DD8,CV2,CV3,CV4,CV5,"sort="&CV6&",DtFmt=1,TmFmt=1,Pos=20,Orient=V,Title=SOL 중단기회사채(A-이상)액티브") -> SOL 중단기회사채(A-이상)액티브 | DI7: =_xll.IMDT("ETP구성",DJ1,DI8:DR8,DJ2,DJ3,DJ4,DJ5,"sort="&DJ6&",DtFmt=1,TmFmt=1,Pos=20,Orient=V,Title=RISE 종합채권(A-이상)액티브") -> RISE 종합채권(A-이상)액티브 | DW7: =_xll.IMDT("ETP구성",DX1,DW8:EF8,DX2,DX3,DX4,DX5,"sort="&DX6&",DtFmt=1,TmFmt=1,Pos=20,Orient=V,Title=SOL 중기종합채권(AA-이상)액티브") -> SOL 중기종합채권(AA-이상)액티브 | EK7: =_xll.IMDT("ETP구성",EL1,EK8:ET8,EL2,EL3,EL4,EL5,"sort="&EL6&",DtFmt=1,TmFmt=1,Pos=20,Orient=V,Title=TIGER 우량회사채액티브") -> TIGER 우량회사채액티브
A8: 일자 | B8: ISIN | C8: 종목코드 | D8: 종목명 | E8: 현재가 | F8: ETF비중 | G8: 보유수량 | H8: 전일평가 | I8: 민평3사가격 | J8: 민평3사듀레이션 | K8: 만기일 | L8: 민평3사 수익률(산출일) | M8: 인포맥스 대분류 | N8: 인포맥스 중분류 | O8: 일자 | P8: ISIN | Q8: 종목코드 | R8: 종목명 | S8: 현재가 | T8: ETF비중 | U8: 보유수량 | V8: 전일평가 | W8: 민평3사가격 | X8: 민평3사듀레이션 | Y8: 만기일 | Z8: 민평3사 수익률(산출일) | AA8: 인포맥스 대분류 | AB8: 인포맥스 중분류 | AC8: 일자 | AD8: ISIN | AE8: 종목코드 | AF8: 종목명 | AG8: 현재가 | AH8: ETF비중 | AI8: 보유수량 | AJ8: 전일평가 | AK8: 민평3사가격 | AL8: 민평3사듀레이션 | AM8: 만기일 | AN8: 민평3사 수익률(산출일) | AO8: 인포맥스 대분류 | AP8: 인포맥스 중분류 | AQ8: 일자 | AR8: ISIN | AS8: 종목코드 | AT8: 종목명 | AU8: 현재가 | AV8: ETF비중 | AW8: 보유수량 | AX8: 전일평가 | AY8: 민평3사가격 | AZ8: 민평3사듀레이션 | BA8: 만기일 | BB8: 민평3사 수익률(산출일) | BC8: 인포맥스 대분류 | BD8: 인포맥스 중분류 | BE8: 일자 | BF8: ISIN | BG8: 종목코드 | BH8: 종목명 | BI8: 현재가 | BJ8: ETF비중 | BK8: 보유수량 | BL8: 전일평가 | BM8: 민평3사가격 | BN8: 민평3사듀레이션 | BO8: 만기일 | BP8: 민평3사 수익률(산출일) | BQ8: 인포맥스 대분류 | BR8: 인포맥스 중분류 | BS8: 일자 | BT8: ISIN | BU8: 종목코드 | BV8: 종목명 | BW8: 현재가 | BX8: ETF비중 | BY8: 보유수량 | BZ8: 전일평가 | CA8: 민평3사가격 | CB8: 민평3사듀레이션 | CC8: 만기일 | CD8: 민평3사 수익률(산출일) | CE8: 인포맥스 대분류 | CF8: 인포맥스 중분류 | CG8: 일자 | CH8: ISIN | CI8: 종목코드 | CJ8: 종목명 | CK8: 현재가 | CL8: ETF비중 | CM8: 보유수량 | CN8: 전일평가 | CO8: 민평3사가격 | CP8: 민평3사듀레이션 | CQ8: 만기일 | CR8: 민평3사 수익률(산출일) | CS8: 인포맥스 대분류 | CT8: 인포맥스 중분류 | CU8: 일자 | CV8: ISIN | CW8: 종목코드 | CX8: 종목명 | CY8: 현재가 | CZ8: ETF비중 | DA8: 보유수량 | DB8: 전일평가 | DC8: 민평3사가격 | DD8: 민평3사듀레이션 | DE8: 만기일 | DF8: 민평3사 수익률(산출일) | DG8: 인포맥스 대분류 | DH8: 인포맥스 중분류 | DI8: 일자 | DJ8: ISIN | DK8: 종목코드 | DL8: 종목명 | DM8: 현재가 | DN8: ETF비중 | DO8: 보유수량 | DP8: 전일평가 | DQ8: 민평3사가격 | DR8: 민평3사듀레이션 | DS8: 만기일 | DT8: 민평3사 수익률(산출일) | DU8: 인포맥스 대분류 | DV8: 인포맥스 중분류 | DW8: 일자 | DX8: ISIN | DY8: 종목코드 | DZ8: 종목명 | EA8: 현재가 | EB8: ETF비중 | EC8: 보유수량 | ED8: 전일평가 | EE8: 민평3사가격 | EF8: 민평3사듀레이션 | EG8: 만기일 | EH8: 민평3사 수익률(산출일) | EI8: 인포맥스 대분류 | EJ8: 인포맥스 중분류 | EK8: 일자 | EL8: ISIN | EM8: 종목코드 | EN8: 종목명 | EO8: 현재가 | EP8: ETF비중 | EQ8: 보유수량 | ER8: 전일평가 | ES8: 민평3사가격 | ET8: 민평3사듀레이션 | EU8: 만기일 | EV8: 민평3사 수익률(산출일) | EW8: 인포맥스 대분류 | EX8: 인포맥스 중분류
A9: 46316 | B9: KR4A656C0009 | C9: A656C000 | D9: 2026-12 국채선물3(신) | E9: 0 | F9: 4.28 | G9: -0.05 | H9: -5153000 | K9: =_xll.IMDP("BND",B9,K8,B3) | L9: =_xll.IMDP("BND",B9,L8,B3) | M9: =_xll.IMDP("BND",B9,M8,B3) | N9: =_xll.IMDP("BND",B9,N8,B3) | O9: 46316 | P9: KR103502GF39 | Q9: 03502G | R9: 국고02625-5503(25-2) | S9: 0 | T9: 9.01 | U9: 0 | V9: 12229731 | W9: 7306.91 | X9: 18.0836 | Y9: =_xll.IMDP("BND",P9,Y8,P3) -> 20550310 | Z9: =_xll.IMDP("BND",P9,Z8,P3) -> 4.293 | AA9: =_xll.IMDP("BND",P9,AA8,P3) -> 국채 | AB9: =_xll.IMDP("BND",P9,AB8,P3) -> 국고채권 | AC9: 46316 | AD9: KR103502G834 | AE9: 03502G | AF9: 국고02625-4803(18-2) | AG9: 0 | AH9: 8.58 | AI9: 0 | AJ9: 12387038 | AK9: 7692.57 | AL9: 15.2744 | AM9: =_xll.IMDP("BND",AD9,AM8,AD3) -> 20480310 | AN9: =_xll.IMDP("BND",AD9,AN8,AD3) -> 4.308 | AO9: =_xll.IMDP("BND",AD9,AO8,AD3) -> 국채 | AP9: =_xll.IMDP("BND",AD9,AP8,AD3) -> 국고채권 | AQ9: 46316 | AR9: KR103503GG60 | AS9: 03503G | AT9: 국고04250-3606(26-6) | AU9: 0 | AV9: 45.45 | AW9: 0 | AX9: 46924924 | AY9: 10212.57 | AZ9: 7.734 | BA9: =_xll.IMDP("BND",AR9,BA8,AR3) -> 20360610 | BB9: =_xll.IMDP("BND",AR9,BB8,AR3) -> 4.175 | BC9: =_xll.IMDP("BND",AR9,BC8,AR3) -> 국채 | BD9: =_xll.IMDP("BND",AR9,BD8,AR3) -> 국고채권 | BE9: 46316 | BF9: KR103501GG62 | BG9: 03501G | BH9: 국고03500-2906(26-5) | BI9: 0 | BJ9: 39.21 | BK9: 0 | BL9: 40467267 | BM9: 10043.24 | BN9: 2.464 | BO9: =_xll.IMDP("BND",BF9,BO8,BF3) -> 20290610 | BP9: =_xll.IMDP("BND",BF9,BP8,BF3) -> 3.835 | BQ9: =_xll.IMDP("BND",BF9,BQ8,BF3) -> 국채 | BR9: =_xll.IMDP("BND",BF9,BR8,BF3) -> 국고채권 | BS9: 46316 | BT9: KR4A656C0009 | BU9: A656C000 | BV9: 2026-12 국채선물3(신) | BW9: 0 | BX9: 2.88 | BY9: 0.04 | BZ9: 4122400 | CC9: =_xll.IMDP("BND",BT9,CC8,BT3) | CD9: =_xll.IMDP("BND",BT9,CD8,BT3) | CE9: =_xll.IMDP("BND",BT9,CE8,BT3) | CF9: =_xll.IMDP("BND",BT9,CF8,BT3) | CG9: 46316 | CH9: KRZS0306167N | CI9: S03061 | CJ9: 교보증권 20260922-30-4(단) | CK9: 0 | CL9: 1.98 | CM9: 0 | CN9: 2508054 | CQ9: =_xll.IMDP("BND",CH9,CQ8,CH3) | CR9: =_xll.IMDP("BND",CH9,CR8,CH3) | CS9: =_xll.IMDP("BND",CH9,CS8,CH3) | CT9: =_xll.IMDP("BND",CH9,CT8,CH3) | CU9: 46316 | CV9: KR6003492F56 | CW9: 003492 | CX9: 대한항공111-2 | CY9: 0 | CZ9: 4.61 | DA9: 0 | DB9: 4778907 | DC9: 9839.5 | DD9: 1.5387 | DE9: =_xll.IMDP("BND",CV9,DE8,CV3) -> 20280526 | DF9: =_xll.IMDP("BND",CV9,DF8,CV3) -> 4.467 | DG9: =_xll.IMDP("BND",CV9,DG8,CV3) -> 회사채 | DH9: =_xll.IMDP("BND",CV9,DH8,CV3) -> 회사채(일반) | DI9: 46316 | DJ9: KR103501GG39 | DK9: 03501G | DL9: 국고채권03500-5603(26-2) | DM9: 0 | DN9: 3.6 | DO9: 0 | DP9: 5691768 | DQ9: 8730.99 | DR9: 17.2848 | DS9: =_xll.IMDP("BND",DJ9,DS8,DJ3) -> 20560310 | DT9: =_xll.IMDP("BND",DJ9,DT8,DJ3) -> 4.287 | DU9: =_xll.IMDP("BND",DJ9,DU8,DJ3) -> 국채 | DV9: =_xll.IMDP("BND",DJ9,DV8,DJ3) -> 국고채권 | DW9: 46316 | DX9: KR103501GFC3 | DY9: 03501G | DZ9: 국고02750-2812(25-10) | EA9: 0 | EB9: 17.67 | EC9: 0 | ED9: 18618326 | EE9: 9888.4 | EF9: 2.0321 | EG9: =_xll.IMDP("BND",DX9,EG8,DX3) -> 20281210 | EH9: =_xll.IMDP("BND",DX9,EH8,DX3) -> 3.787 | EI9: =_xll.IMDP("BND",DX9,EI8,DX3) -> 국채 | EJ9: =_xll.IMDP("BND",DX9,EJ8,DX3) -> 국고채권 | EK9: 46316 | EL9: KR4A676C0005 | EM9: A676C000 | EN9: 10년국채 F 202612 | EO9: 0 | EP9: 5.45 | EQ9: -0.1171 | ER9: -12479347 | EU9: =_xll.IMDP("BND",EL9,EU8,EL3) | EV9: =_xll.IMDP("BND",EL9,EV8,EL3) | EW9: =_xll.IMDP("BND",EL9,EW8,EL3) | EX9: =_xll.IMDP("BND",EL9,EX8,EL3)
A10: 46316 | B10: KR103502GD98 | C10: 03502G | D10: 국고03625-5309(23-7) | E10: 0 | F10: 2.22 | G10: 0 | H10: 2673193 | I10: 8958.96 | J10: 16.3566 | K10: =_xll.IMDP("BND",B10,K8,B3) -> 20530910 | L10: =_xll.IMDP("BND",B10,L8,B3) -> 4.308 | M10: =_xll.IMDP("BND",B10,M8,B3) -> 국채 | N10: =_xll.IMDP("BND",B10,N8,B3) -> 국고채권 | O10: 46316 | P10: KR103502GFC1 | Q10: 03502G | R10: 국고03250-3512(25-11) | S10: 0 | T10: 7.37 | U10: 0 | V10: 10001298 | W10: 9424.3 | X10: 7.67 | Y10: =_xll.IMDP("BND",P10,Y8,P3) -> 20351210 | Z10: =_xll.IMDP("BND",P10,Z8,P3) -> 4.17 | AA10: =_xll.IMDP("BND",P10,AA8,P3) -> 국채 | AB10: =_xll.IMDP("BND",P10,AB8,P3) -> 국고채권 | AC10: 46316 | AD10: KR4A676C0005 | AE10: A676C000 | AF10: 2026-12 국채선물10(신) | AG10: 0 | AH10: 8.12 | AI10: -0.11 | AJ10: -11722700 | AM10: =_xll.IMDP("BND",AD10,AM8,AD3) | AN10: =_xll.IMDP("BND",AD10,AN8,AD3) | AO10: =_xll.IMDP("BND",AD10,AO8,AD3) | AP10: =_xll.IMDP("BND",AD10,AP8,AD3) | AQ10: 46316 | AR10: KR103502GFC1 | AS10: 03502G | AT10: 국고03250-3512(25-11) | AU10: 0 | AV10: 33.56 | AW10: 0 | AX10: 34642372 | AY10: 9424.3 | AZ10: 7.67 | BA10: =_xll.IMDP("BND",AR10,BA8,AR3) -> 20351210 | BB10: =_xll.IMDP("BND",AR10,BB8,AR3) -> 4.17 | BC10: =_xll.IMDP("BND",AR10,BC8,AR3) -> 국채 | BD10: =_xll.IMDP("BND",AR10,BD8,AR3) -> 국고채권 | BE10: 46316 | BF10: KR103503GG37 | BG10: 03503G | BH10: 국고03375-3103(26-3) | BI10: 0 | BJ10: 30.23 | BK10: 0 | BL10: 31196797 | BM10: 9789.18 | BN10: 4.0153 | BO10: =_xll.IMDP("BND",BF10,BO8,BF3) -> 20310310 | BP10: =_xll.IMDP("BND",BF10,BP8,BF3) -> 3.998 | BQ10: =_xll.IMDP("BND",BF10,BQ8,BF3) -> 국채 | BR10: =_xll.IMDP("BND",BF10,BR8,BF3) -> 국고채권 | BS10: 46316 | BT10: KR103501GG39 | BU10: 03501G | BV10: 국고03500-5603(26-2) | BW10: 0 | BX10: 2.69 | BY10: 0 | BZ10: 3842416 | CA10: 8730.99 | CB10: 17.2848 | CC10: =_xll.IMDP("BND",BT10,CC8,BT3) -> 20560310 | CD10: =_xll.IMDP("BND",BT10,CD8,BT3) -> 4.287 | CE10: =_xll.IMDP("BND",BT10,CE8,BT3) -> 국채 | CF10: =_xll.IMDP("BND",BT10,CF8,BT3) -> 국고채권 | CG10: 46316 | CH10: KRZS47670014 | CI10: S47670 | CJ10: 모멘텀제일차 20260820-92-1(단) | CK10: 0 | CL10: 1.97 | CM10: 0 | CN10: 2500878 | CQ10: =_xll.IMDP("BND",CH10,CQ8,CH3) | CR10: =_xll.IMDP("BND",CH10,CR8,CH3) | CS10: =_xll.IMDP("BND",CH10,CS8,CH3) | CT10: =_xll.IMDP("BND",CH10,CT8,CH3) | CU10: 46316 | CV10: KR6023769G75 | CW10: 023769 | CX10: 한국캐피탈571-4 | CY10: 0 | CZ10: 2.37 | DA10: 0 | DB10: 2453608 | DC10: 10105.41 | DD10: 1.2904 | DE10: =_xll.IMDP("BND",CV10,DE8,CV3) -> 20280229 | DF10: =_xll.IMDP("BND",CV10,DF8,CV3) -> 5.057 | DG10: =_xll.IMDP("BND",CV10,DG8,CV3) -> 금융채 | DH10: =_xll.IMDP("BND",CV10,DH8,CV3) -> 기타금융채 | DI10: 46316 | DJ10: KR103502GG95 | DK10: 03502G | DL10: 국고채권04500-5609(26-8) | DM10: 0 | DN10: 3.04 | DO10: 0 | DP10: 4808692 | DQ10: 10441.59 | DR10: 16.5401 | DS10: =_xll.IMDP("BND",DJ10,DS8,DJ3) -> 20560910 | DT10: =_xll.IMDP("BND",DJ10,DT8,DJ3) -> 4.267 | DU10: =_xll.IMDP("BND",DJ10,DU8,DJ3) -> 국채 | DV10: =_xll.IMDP("BND",DJ10,DV8,DJ3) -> 국고채권 | DW10: 46316 | DX10: KR103501GG62 | DY10: 03501G | DZ10: 국고03500-2906(26-5) | EA10: 0 | EB10: 13.96 | EC10: 0 | ED10: 14707673 | EE10: 10043.24 | EF10: 2.464 | EG10: =_xll.IMDP("BND",DX10,EG8,DX3) -> 20290610 | EH10: =_xll.IMDP("BND",DX10,EH8,DX3) -> 3.835 | EI10: =_xll.IMDP("BND",DX10,EI8,DX3) -> 국채 | EJ10: =_xll.IMDP("BND",DX10,EJ8,DX3) -> 국고채권 | EK10: 46316 | EL10: KR4A656C0009 | EM10: A656C000 | EN10: 3년국채 F 202612 | EO10: 0 | EP10: 4.01 | EQ10: 0.089 | ER10: 9172340 | EU10: =_xll.IMDP("BND",EL10,EU8,EL3) | EV10: =_xll.IMDP("BND",EL10,EV8,EL3) | EW10: =_xll.IMDP("BND",EL10,EW8,EL3) | EX10: =_xll.IMDP("BND",EL10,EX8,EL3)
A11: 46316 | B11: KR103501GG39 | C11: 03501G | D11: 국고03500-5603(26-2) | E11: 0 | F11: 2.04 | G11: 0 | H11: 2451213 | I11: 8730.99 | J11: 17.2848 | K11: =_xll.IMDP("BND",B11,K8,B3) -> 20560310 | L11: =_xll.IMDP("BND",B11,L8,B3) -> 4.287 | M11: =_xll.IMDP("BND",B11,M8,B3) -> 국채 | N11: =_xll.IMDP("BND",B11,N8,B3) -> 국고채권 | O11: 46316 | P11: KR356115GFB8 | Q11: 56115G | R11: 토지주택채권559 | S11: 0 | T11: 5.83 | U11: 0 | V11: 7917028 | W11: 9697.87 | X11: 3.7893 | Y11: =_xll.IMDP("BND",P11,Y8,P3) -> 20301127 | Z11: =_xll.IMDP("BND",P11,Z8,P3) -> 4.233 | AA11: =_xll.IMDP("BND",P11,AA8,P3) -> 공사공단채 | AB11: =_xll.IMDP("BND",P11,AB8,P3) -> 일반 | AC11: 46316 | AD11: KR103502GC99 | AE11: 03502G | AF11: 국고03125-5209(22-9) | AG11: 0 | AH11: 7.13 | AI11: 0 | AJ11: 10284042 | AK11: 8183.03 | AL11: 16.5318 | AM11: =_xll.IMDP("BND",AD11,AM8,AD3) -> 20520910 | AN11: =_xll.IMDP("BND",AD11,AN8,AD3) -> 4.32 | AO11: =_xll.IMDP("BND",AD11,AO8,AD3) -> 국채 | AP11: =_xll.IMDP("BND",AD11,AP8,AD3) -> 국고채권 | AQ11: 46316 | AR11: KR103502GF62 | AS11: 03502G | AT11: 국고채권02625-3506(25-5) | AU11: 0 | AV11: 9.81 | AW11: 0 | AX11: 10132127 | AY11: 8983.82 | AZ11: 7.4838 | BA11: =_xll.IMDP("BND",AR11,BA8,AR3) -> 20350610 | BB11: =_xll.IMDP("BND",AR11,BB8,AR3) -> 4.17 | BC11: =_xll.IMDP("BND",AR11,BC8,AR3) -> 국채 | BD11: =_xll.IMDP("BND",AR11,BD8,AR3) -> 국고채권 | BE11: 46316 | BF11: KR103501GFC3 | BG11: 03501G | BH11: 국고02750-2812(25-10) | BI11: 0 | BJ11: 27.22 | BK11: 0 | BL11: 28089575 | BM11: 9888.4 | BN11: 2.0321 | BO11: =_xll.IMDP("BND",BF11,BO8,BF3) -> 20281210 | BP11: =_xll.IMDP("BND",BF11,BP8,BF3) -> 3.787 | BQ11: =_xll.IMDP("BND",BF11,BQ8,BF3) -> 국채 | BR11: =_xll.IMDP("BND",BF11,BR8,BF3) -> 국고채권 | BS11: 46316 | BT11: KR103502GA67 | BU11: 03502G | BV11: 국고채권01375-3006(20-4) | BW11: 0 | BX11: 2.52 | BY11: 0 | BZ11: 3606381 | CA11: 9184.15 | CB11: 3.4692 | CC11: =_xll.IMDP("BND",BT11,CC8,BT3) -> 20300610 | CD11: =_xll.IMDP("BND",BT11,CD8,BT3) -> 3.953 | CE11: =_xll.IMDP("BND",BT11,CE8,BT3) -> 국채 | CF11: =_xll.IMDP("BND",BT11,CF8,BT3) -> 국고채권 | CG11: 46316 | CH11: KRZS49313040 | CI11: S49313 | CJ11: 에스디비제오차 20260831-91-1(단) | CK11: 0 | CL11: 1.92 | CM11: 0 | CN11: 2432710 | CQ11: =_xll.IMDP("BND",CH11,CQ8,CH3) | CR11: =_xll.IMDP("BND",CH11,CR8,CH3) | CS11: =_xll.IMDP("BND",CH11,CS8,CH3) | CT11: =_xll.IMDP("BND",CH11,CT8,CH3) | CU11: 46316 | CV11: KR6003491G98 | CW11: 003491 | CX11: 대한항공122-1 | CY11: 0 | CZ11: 2.37 | DA11: 0 | DB11: 2449254 | DC11: 10084.06 | DD11: 1.8026 | DE11: =_xll.IMDP("BND",CV11,DE8,CV3) -> 20280915 | DF11: =_xll.IMDP("BND",CV11,DF8,CV3) -> 4.601 | DG11: =_xll.IMDP("BND",CV11,DG8,CV3) -> 회사채 | DH11: =_xll.IMDP("BND",CV11,DH8,CV3) -> 회사채(일반) | DI11: 46316 | DJ11: KR103504GE95 | DK11: 03504G | DL11: 국고채권02875-4409(24-10) | DM11: 0 | DN11: 1.51 | DO11: 0 | DP11: 2381147 | DQ11: 8316.35 | DR11: 13.3243 | DS11: =_xll.IMDP("BND",DJ11,DS8,DJ3) -> 20440910 | DT11: =_xll.IMDP("BND",DJ11,DT8,DJ3) -> 4.254 | DU11: =_xll.IMDP("BND",DJ11,DU8,DJ3) -> 국채 | DV11: =_xll.IMDP("BND",DJ11,DV8,DJ3) -> 국고채권 | DW11: 46316 | DX11: KR103503GG37 | DY11: 03503G | DZ11: 국고03375-3103(26-3) | EA11: 0 | EB11: 7.19 | EC11: 0 | ED11: 7577522 | EE11: 9789.18 | EF11: 4.0153 | EG11: =_xll.IMDP("BND",DX11,EG8,DX3) -> 20310310 | EH11: =_xll.IMDP("BND",DX11,EH8,DX3) -> 3.998 | EI11: =_xll.IMDP("BND",DX11,EI8,DX3) -> 국채 | EJ11: =_xll.IMDP("BND",DX11,EJ8,DX3) -> 국고채권 | EK11: 46316 | EL11: KR70000Y0004 | EM11: 0000Y0 | EN11: HK 26-12 회사채(AA-이상)액티브 | EO11: 102265 | EP11: 2.09 | EQ11: 46.8603 | ER11: 4792168 | EU11: =_xll.IMDP("BND",EL11,EU8,EL3) | EV11: =_xll.IMDP("BND",EL11,EV8,EL3) | EW11: =_xll.IMDP("BND",EL11,EW8,EL3) | EX11: =_xll.IMDP("BND",EL11,EX8,EL3)
A12: 46316 | B12: KR103502GB33 | C12: 03502G | D12: 국고01875-5103(21-2) | E12: 0 | F12: 1.35 | G12: 0 | H12: 1631393 | I12: 6402.24 | J12: 17.7604 | K12: =_xll.IMDP("BND",B12,K8,B3) -> 20510310 | L12: =_xll.IMDP("BND",B12,L8,B3) -> 4.28 | M12: =_xll.IMDP("BND",B12,M8,B3) -> 국채 | N12: =_xll.IMDP("BND",B12,N8,B3) -> 국고채권 | O12: 46316 | P12: KR103502GE30 | Q12: 03502G | R12: 국고03250-5403(24-2) | S12: 0 | T12: 5.52 | U12: 0 | V12: 7496253 | W12: 8346.45 | X12: 16.9163 | Y12: =_xll.IMDP("BND",P12,Y8,P3) -> 20540310 | Z12: =_xll.IMDP("BND",P12,Z8,P3) -> 4.306 | AA12: =_xll.IMDP("BND",P12,AA8,P3) -> 국채 | AB12: =_xll.IMDP("BND",P12,AB8,P3) -> 국고채권 | AC12: 46316 | AD12: KR103502GE97 | AE12: 03502G | AF12: 국고02750-5409(24-8) | AG12: 0 | AH12: 6.35 | AI12: 0 | AJ12: 9171070 | AK12: 7534.48 | AL12: 17.7308 | AM12: =_xll.IMDP("BND",AD12,AM8,AD3) -> 20540910 | AN12: =_xll.IMDP("BND",AD12,AN8,AD3) -> 4.294 | AO12: =_xll.IMDP("BND",AD12,AO8,AD3) -> 국채 | AP12: =_xll.IMDP("BND",AD12,AP8,AD3) -> 국고채권 | AQ12: 46316 | AR12: KR103502GDC6 | AS12: 03502G | AT12: 국고04125-3312(23-11) | AU12: 0 | AV12: 3.29 | AW12: 0 | AX12: 3399703 | AY12: 10173.61 | AZ12: 6.0438 | BA12: =_xll.IMDP("BND",AR12,BA8,AR3) -> 20331210 | BB12: =_xll.IMDP("BND",AR12,BB8,AR3) -> 4.085 | BC12: =_xll.IMDP("BND",AR12,BC8,AR3) -> 국채 | BD12: =_xll.IMDP("BND",AR12,BD8,AR3) -> 국고채권 | BE12: 46316 | BF12: KR4A656C0009 | BG12: A656C000 | BH12: 2026-12 국채선물3(신) | BI12: 0 | BJ12: 2 | BK12: 0.02 | BL12: 2061200 | BO12: =_xll.IMDP("BND",BF12,BO8,BF3) | BP12: =_xll.IMDP("BND",BF12,BP8,BF3) | BQ12: =_xll.IMDP("BND",BF12,BQ8,BF3) | BR12: =_xll.IMDP("BND",BF12,BR8,BF3) | BS12: 46316 | BT12: KR103502GF39 | BU12: 03502G | BV12: 국고02625-5503(25-2) | BW12: 0 | BX12: 2.32 | BY12: 0 | BZ12: 3316982 | CA12: 7306.91 | CB12: 18.0836 | CC12: =_xll.IMDP("BND",BT12,CC8,BT3) -> 20550310 | CD12: =_xll.IMDP("BND",BT12,CD8,BT3) -> 4.293 | CE12: =_xll.IMDP("BND",BT12,CE8,BT3) -> 국채 | CF12: =_xll.IMDP("BND",BT12,CF8,BT3) -> 국고채권 | CG12: 46316 | CH12: KRZS0078P045 | CI12: S0078P | CJ12: 트루프렌드상생제일차 20261012-29-3(단) | CK12: 0 | CL12: 1.81 | CM12: 0 | CN12: 2297785 | CQ12: =_xll.IMDP("BND",CH12,CQ8,CH3) | CR12: =_xll.IMDP("BND",CH12,CR8,CH3) | CS12: =_xll.IMDP("BND",CH12,CS8,CH3) | CT12: =_xll.IMDP("BND",CH12,CT8,CH3) | CU12: 46316 | CV12: KR6103342G97 | CW12: 103342 | CX12: 대신에프앤아이45-2 | CY12: 0 | CZ12: 2.36 | DA12: 0 | DB12: 2448773 | DC12: 10083.42 | DD12: 2.6727 | DE12: =_xll.IMDP("BND",CV12,DE8,CV3) -> 20290914 | DF12: =_xll.IMDP("BND",CV12,DF8,CV3) -> 4.902 | DG12: =_xll.IMDP("BND",CV12,DG8,CV3) -> 회사채 | DH12: =_xll.IMDP("BND",CV12,DH8,CV3) -> 회사채(일반) | DI12: 46316 | DJ12: KR6000013G85 | DK12: 000013 | DL12: 신한은행30-08-이-1.25-A | DM12: 0 | DN12: 1.21 | DO12: 0 | DP12: 1917304 | DQ12: 10043.68 | DR12: 1.022 | DS12: =_xll.IMDP("BND",DJ12,DS8,DJ3) -> 20271110 | DT12: =_xll.IMDP("BND",DJ12,DT8,DJ3) -> 4.037 | DU12: =_xll.IMDP("BND",DJ12,DU8,DJ3) -> 금융채 | DV12: =_xll.IMDP("BND",DJ12,DV8,DJ3) -> 은행채 | DW12: 46316 | DX12: KR6145768FC3 | DY12: 145768 | DZ12: BNK캐피탈385-6 | EA12: 0 | EB12: 5.85 | EC12: 0 | ED12: 6158548 | EE12: 9812.58 | EF12: 2.082 | EG12: =_xll.IMDP("BND",DX12,EG8,DX3) -> 20281226 | EH12: =_xll.IMDP("BND",DX12,EH8,DX3) -> 4.514 | EI12: =_xll.IMDP("BND",DX12,EI8,DX3) -> 금융채 | EJ12: =_xll.IMDP("BND",DX12,EJ8,DX3) -> 기타금융채 | EK12: 46316 | EL12: KR70192Z0001 | EM12: 0192Z0 | EN12: TIGER 중기종합채권(A-이상)액티브 | EO12: 101455 | EP12: 2.08 | EQ12: 46.8603 | ER12: 4754211 | EU12: =_xll.IMDP("BND",EL12,EU8,EL3) | EV12: =_xll.IMDP("BND",EL12,EV8,EL3) | EW12: =_xll.IMDP("BND",EL12,EW8,EL3) | EX12: =_xll.IMDP("BND",EL12,EX8,EL3)
A13: 46316 | B13: KR103502GE30 | C13: 03502G | D13: 국고03250-5403(24-2) | E13: 0 | F13: 1.3 | G13: 0 | H13: 1567779 | I13: 8346.45 | J13: 16.9163 | K13: =_xll.IMDP("BND",B13,K8,B3) -> 20540310 | L13: =_xll.IMDP("BND",B13,L8,B3) -> 4.306 | M13: =_xll.IMDP("BND",B13,M8,B3) -> 국채 | N13: =_xll.IMDP("BND",B13,N8,B3) -> 국고채권 | O13: 46316 | P13: KR103503GF95 | Q13: 03503G | R13: 국고02500-3009(25-8) | S13: 0 | T13: 4.86 | U13: 0 | V13: 6592982 | W13: 9501.73 | X13: 3.6419 | Y13: =_xll.IMDP("BND",P13,Y8,P3) -> 20300910 | Z13: =_xll.IMDP("BND",P13,Z8,P3) -> 3.974 | AA13: =_xll.IMDP("BND",P13,AA8,P3) -> 국채 | AB13: =_xll.IMDP("BND",P13,AB8,P3) -> 국고채권 | AC13: 46316 | AD13: KR103504GD96 | AE13: 03504G | AF13: 국고03875-4309(23-9) | AG13: 0 | AH13: 6.32 | AI13: 0 | AJ13: 9116168 | AK13: 9557.03 | AL13: 12.108 | AM13: =_xll.IMDP("BND",AD13,AM8,AD3) -> 20430910 | AN13: =_xll.IMDP("BND",AD13,AN8,AD3) -> 4.282 | AO13: =_xll.IMDP("BND",AD13,AO8,AD3) -> 국채 | AP13: =_xll.IMDP("BND",AD13,AP8,AD3) -> 국고채권 | AQ13: 46316 | AR13: KR4A676C0005 | AS13: A676C000 | AT13: 2026-12 국채선물10(신) | AU13: 0 | AV13: 3.1 | AW13: 0.03 | AX13: 3197100 | BA13: =_xll.IMDP("BND",AR13,BA8,AR3) | BB13: =_xll.IMDP("BND",AR13,BB8,AR3) | BC13: =_xll.IMDP("BND",AR13,BC8,AR3) | BD13: =_xll.IMDP("BND",AR13,BD8,AR3) | BE13: 46316 | BF13: KR103501GEC6 | BG13: 03501G | BH13: 국고02875-2712(24-12) | BI13: 0 | BJ13: 0.89 | BK13: 0 | BL13: 917202 | BM13: 10015.97 | BN13: 1.0962 | BO13: =_xll.IMDP("BND",BF13,BO8,BF3) -> 20271210 | BP13: =_xll.IMDP("BND",BF13,BP8,BF3) -> 3.671 | BQ13: =_xll.IMDP("BND",BF13,BQ8,BF3) -> 국채 | BR13: =_xll.IMDP("BND",BF13,BR8,BF3) -> 국고채권 | BS13: 46316 | BT13: KR103502GF96 | BU13: 03502G | BV13: 국고02625-5509(25-7) | BW13: 0 | BX13: 2.06 | BY13: 0 | BZ13: 2951373 | CA13: 7289.55 | CB13: 18.2572 | CC13: =_xll.IMDP("BND",BT13,CC8,BT3) -> 20550910 | CD13: =_xll.IMDP("BND",BT13,CD8,BT3) -> 4.288 | CE13: =_xll.IMDP("BND",BT13,CE8,BT3) -> 국채 | CF13: =_xll.IMDP("BND",BT13,CF8,BT3) -> 국고채권 | CG13: 46316 | CH13: KR6025083DB9 | CI13: 025083 | CJ13: 하나에프앤아이186-3 | CK13: 0 | CL13: 1.62 | CM13: 0 | CN13: 2050738 | CO13: 10121.54 | CP13: 0.0443 | CQ13: =_xll.IMDP("BND",CH13,CQ8,CH3) -> 20261106 | CR13: =_xll.IMDP("BND",CH13,CR8,CH3) -> 3.648 | CS13: =_xll.IMDP("BND",CH13,CS8,CH3) -> 회사채 | CT13: =_xll.IMDP("BND",CH13,CT8,CH3) -> 회사채(일반) | CU13: 46316 | CV13: KR6028671EA8 | CW13: 028671 | CX13: 팬오션22 | CY13: 0 | CZ13: 2.36 | DA13: 0 | DB13: 2448258 | DC13: 10081.91 | DD13: 0.0251 | DE13: =_xll.IMDP("BND",CV13,DE8,CV3) -> 20261030 | DF13: =_xll.IMDP("BND",CV13,DF8,CV3) -> 3.62 | DG13: =_xll.IMDP("BND",CV13,DG8,CV3) -> 회사채 | DH13: =_xll.IMDP("BND",CV13,DH8,CV3) -> 회사채(일반) | DI13: 46316 | DJ13: KR103502GF39 | DK13: 03502G | DL13: 국고채권02625-5503(25-2) | DM13: 0 | DN13: 1.1 | DO13: 0 | DP13: 1735259 | DQ13: 7306.91 | DR13: 18.0836 | DS13: =_xll.IMDP("BND",DJ13,DS8,DJ3) -> 20550310 | DT13: =_xll.IMDP("BND",DJ13,DT8,DJ3) -> 4.293 | DU13: =_xll.IMDP("BND",DJ13,DU8,DJ3) -> 국채 | DV13: =_xll.IMDP("BND",DJ13,DV8,DJ3) -> 국고채권 | DW13: 46316 | DX13: KR6139132F88 | DY13: 139132 | DZ13: iM금융지주28-2 | EA13: 0 | EB13: 5.66 | EC13: 0 | ED13: 5966573 | EE13: 9507.11 | EF13: 3.6028 | EG13: =_xll.IMDP("BND",DX13,EG8,DX3) -> 20300829 | EH13: =_xll.IMDP("BND",DX13,EH8,DX3) -> 4.392 | EI13: =_xll.IMDP("BND",DX13,EI8,DX3) -> 회사채 | EJ13: =_xll.IMDP("BND",DX13,EJ8,DX3) -> 회사채(일반) | EK13: 46316 | EL13: KR603062AE52 | EM13: 03062A | EN13: 롯데카드531-3 | EO13: 0 | EP13: 2.06 | EQ13: 0 | ER13: 4722450 | ES13: 10077.59 | ET13: 0.0633 | EU13: =_xll.IMDP("BND",EL13,EU8,EL3) -> 20261113 | EV13: =_xll.IMDP("BND",EL13,EV8,EL3) -> 3.795 | EW13: =_xll.IMDP("BND",EL13,EW8,EL3) -> 금융채 | EX13: =_xll.IMDP("BND",EL13,EX8,EL3) -> 카드
A14: 46316 | B14: KR103502G792 | C14: 03502G | D14: 국고02250-3709(17-5) | E14: 0 | F14: 1.15 | G14: 0 | H14: 1383854 | I14: 8348.1 | J14: 9.3531 | K14: =_xll.IMDP("BND",B14,K8,B3) -> 20370910 | L14: =_xll.IMDP("BND",B14,L8,B3) -> 4.183 | M14: =_xll.IMDP("BND",B14,M8,B3) -> 국채 | N14: =_xll.IMDP("BND",B14,N8,B3) -> 국고채권 | O14: 46316 | P14: KR103502GEC4 | Q14: 03502G | R14: 국고03000-3412(24-13) | S14: 0 | T14: 4.49 | U14: 0 | V14: 6092871 | W14: 9330.42 | X14: 7.0099 | Y14: =_xll.IMDP("BND",P14,Y8,P3) -> 20341210 | Z14: =_xll.IMDP("BND",P14,Z8,P3) -> 4.135 | AA14: =_xll.IMDP("BND",P14,AA8,P3) -> 국채 | AB14: =_xll.IMDP("BND",P14,AB8,P3) -> 국고채권 | AC14: 46316 | AD14: KR103502G933 | AE14: 03502G | AF14: 국고02000-4903(19-2) | AG14: 0 | AH14: 6.28 | AI14: 0 | AJ14: 9063817 | AK14: 6719.49 | AL14: 16.5686 | AM14: =_xll.IMDP("BND",AD14,AM8,AD3) -> 20490310 | AN14: =_xll.IMDP("BND",AD14,AN8,AD3) -> 4.315 | AO14: =_xll.IMDP("BND",AD14,AO8,AD3) -> 국채 | AP14: =_xll.IMDP("BND",AD14,AP8,AD3) -> 국고채권 | AQ14: 46316 | AR14: KR103502GCC8 | AS14: 03502G | AT14: 국고04250-3212(22-14) | AU14: 0 | AV14: 1.63 | AW14: 0 | AX14: 1684625 | AY14: 10288.1 | AZ14: 5.2871 | BA14: =_xll.IMDP("BND",AR14,BA8,AR3) -> 20321210 | BB14: =_xll.IMDP("BND",AR14,BB8,AR3) -> 4 | BC14: =_xll.IMDP("BND",AR14,BC8,AR3) -> 국채 | BD14: =_xll.IMDP("BND",AR14,BD8,AR3) -> 국고채권 | BE14: 46316 | BF14: KR103503GF38 | BG14: 03503G | BH14: 국고02625-3003(25-3) | BI14: 0 | BJ14: 0.26 | BK14: 0 | BL14: 264244 | BM14: 9618.51 | BN14: 3.1881 | BO14: =_xll.IMDP("BND",BF14,BO8,BF3) -> 20300310 | BP14: =_xll.IMDP("BND",BF14,BP8,BF3) -> 3.932 | BQ14: =_xll.IMDP("BND",BF14,BQ8,BF3) -> 국채 | BR14: =_xll.IMDP("BND",BF14,BR8,BF3) -> 국고채권 | BS14: 46316 | BT14: KR103503GG60 | BU14: 03503G | BV14: 국고04250-3606(26-6) | BW14: 0 | BX14: 1.55 | BY14: 0 | BZ14: 2222763 | CA14: 10212.57 | CB14: 7.734 | CC14: =_xll.IMDP("BND",BT14,CC8,BT3) -> 20360610 | CD14: =_xll.IMDP("BND",BT14,CD8,BT3) -> 4.175 | CE14: =_xll.IMDP("BND",BT14,CE8,BT3) -> 국채 | CF14: =_xll.IMDP("BND",BT14,CF8,BT3) -> 국고채권 | CG14: 46316 | CH14: KR6167161F18 | CI14: 167161 | CJ14: 벤츠파이낸셜44 | CK14: 0 | CL14: 1.61 | CM14: 0 | CN14: 2039669 | CO14: 10066.74 | CP14: 0.2513 | CQ14: =_xll.IMDP("BND",CH14,CQ8,CH3) -> 20270122 | CR14: =_xll.IMDP("BND",CH14,CR8,CH3) -> 3.71 | CS14: =_xll.IMDP("BND",CH14,CS8,CH3) -> 금융채 | CT14: =_xll.IMDP("BND",CH14,CT8,CH3) -> 기타금융채 | CU14: 46316 | CV14: KR6095236G78 | CW14: 095236 | CX14: 애큐온캐피탈261-3 | CY14: 0 | CZ14: 2.36 | DA14: 0 | DB14: 2447173 | DC14: 10077.45 | DD14: 1.8136 | DE14: =_xll.IMDP("BND",CV14,DE8,CV3) -> 20280929 | DF14: =_xll.IMDP("BND",CV14,DF8,CV3) -> 5.426 | DG14: =_xll.IMDP("BND",CV14,DG8,CV3) -> 금융채 | DH14: =_xll.IMDP("BND",CV14,DH8,CV3) -> 기타금융채 | DI14: 46316 | DJ14: KR103503GF95 | DK14: 03503G | DL14: 국고채권02500-3009(25-8) | DM14: 0 | DN14: 1.09 | DO14: 0 | DP14: 1723109 | DQ14: 9501.73 | DR14: 3.6419 | DS14: =_xll.IMDP("BND",DJ14,DS8,DJ3) -> 20300910 | DT14: =_xll.IMDP("BND",DJ14,DT8,DJ3) -> 3.974 | DU14: =_xll.IMDP("BND",DJ14,DU8,DJ3) -> 국채 | DV14: =_xll.IMDP("BND",DJ14,DV8,DJ3) -> 국고채권 | DW14: 46316 | DX14: KR103503GF38 | DY14: 03503G | DZ14: 국고02625-3003(25-3) | EA14: 0 | EB14: 5.16 | EC14: 0 | ED14: 5433050 | EE14: 9618.51 | EF14: 3.1881 | EG14: =_xll.IMDP("BND",DX14,EG8,DX3) -> 20300310 | EH14: =_xll.IMDP("BND",DX14,EH8,DX3) -> 3.932 | EI14: =_xll.IMDP("BND",DX14,EI8,DX3) -> 국채 | EJ14: =_xll.IMDP("BND",DX14,EJ8,DX3) -> 국고채권 | EK14: 46316 | EL14: KR6029272F24 | EM14: 029272 | EN14: 에스케이실트론52-2 | EO14: 0 | EP14: 2.03 | EQ14: 0 | ER14: 4646621 | ES14: 9915.75 | ET14: 1.291 | EU14: =_xll.IMDP("BND",EL14,EU8,EL3) -> 20280221 | EV14: =_xll.IMDP("BND",EL14,EV8,EL3) -> 4.398 | EW14: =_xll.IMDP("BND",EL14,EW8,EL3) -> 회사채 | EX14: =_xll.IMDP("BND",EL14,EX8,EL3) -> 회사채(일반)
A15: 46316 | B15: KR103502GE97 | C15: 03502G | D15: 국고02750-5409(24-8) | E15: 0 | F15: 1.02 | G15: 0 | H15: 1234031 | I15: 7534.48 | J15: 17.7308 | K15: =_xll.IMDP("BND",B15,K8,B3) -> 20540910 | L15: =_xll.IMDP("BND",B15,L8,B3) -> 4.294 | M15: =_xll.IMDP("BND",B15,M8,B3) -> 국채 | N15: =_xll.IMDP("BND",B15,N8,B3) -> 국고채권 | O15: 46316 | P15: KR602378BD79 | Q15: 02378B | R15: 신한캐피탈483-2 | S15: 0 | T15: 3.09 | U15: 0 | V15: 4193081 | W15: 10273.28 | X15: 3.3823 | Y15: =_xll.IMDP("BND",P15,Y8,P3) -> 20300726 | Z15: =_xll.IMDP("BND",P15,Z8,P3) -> 4.513 | AA15: =_xll.IMDP("BND",P15,AA8,P3) -> 금융채 | AB15: =_xll.IMDP("BND",P15,AB8,P3) -> 기타금융채 | AC15: 46316 | AD15: KR103502GD31 | AE15: 03502G | AF15: 국고03250-5303(23-2) | AG15: 0 | AH15: 5.88 | AI15: 0 | AJ15: 8479289 | AK15: 8367.21 | AL15: 16.5705 | AM15: =_xll.IMDP("BND",AD15,AM8,AD3) -> 20530310 | AN15: =_xll.IMDP("BND",AD15,AN8,AD3) -> 4.315 | AO15: =_xll.IMDP("BND",AD15,AO8,AD3) -> 국채 | AP15: =_xll.IMDP("BND",AD15,AP8,AD3) -> 국고채권 | AQ15: 46316 | AR15: KR103502GD64 | AS15: 03502G | AT15: 국고03250-3306(23-5) | AU15: 0 | AV15: 0.78 | AW15: 0 | AX15: 807030 | AY15: 9660.19 | AZ15: 5.8173 | BA15: =_xll.IMDP("BND",AR15,BA8,AR3) -> 20330610 | BB15: =_xll.IMDP("BND",AR15,BB8,AR3) -> 4.042 | BC15: =_xll.IMDP("BND",AR15,BC8,AR3) -> 국채 | BD15: =_xll.IMDP("BND",AR15,BD8,AR3) -> 국고채권 | BE15: 46316 | BF15: KR103501GF63 | BG15: 03501G | BH15: 국고02250-2806(25-4) | BI15: 0 | BJ15: 0.17 | BK15: 0 | BL15: 180329 | BM15: 9846.01 | BN15: 1.5749 | BO15: =_xll.IMDP("BND",BF15,BO8,BF3) -> 20280610 | BP15: =_xll.IMDP("BND",BF15,BP8,BF3) -> 3.745 | BQ15: =_xll.IMDP("BND",BF15,BQ8,BF3) -> 국채 | BR15: =_xll.IMDP("BND",BF15,BR8,BF3) -> 국고채권 | BS15: 46316 | BT15: KR103503GG94 | BU15: 03503G | BV15: 국고00000-3109(26-9) | BW15: 0 | BX15: 1.47 | BY15: 0 | BZ15: 2098120 | CA15: 10107.63 | CB15: 4.3722 | CC15: =_xll.IMDP("BND",BT15,CC8,BT3) -> 20310910 | CD15: =_xll.IMDP("BND",BT15,CD8,BT3) -> 3.985 | CE15: =_xll.IMDP("BND",BT15,CE8,BT3) -> 국채 | CF15: =_xll.IMDP("BND",BT15,CF8,BT3) -> 국고채권 | CG15: 46316 | CH15: KR6089862E25 | CI15: 089862 | CJ15: 롯데렌탈60-2 | CK15: 0 | CL15: 1.59 | CM15: 0 | CN15: 2015890 | CO15: 10111.54 | CP15: 0.2788 | CQ15: =_xll.IMDP("BND",CH15,CQ8,CH3) -> 20270202 | CR15: =_xll.IMDP("BND",CH15,CR8,CH3) -> 3.888 | CS15: =_xll.IMDP("BND",CH15,CS8,CH3) -> 회사채 | CT15: =_xll.IMDP("BND",CH15,CT8,CH3) -> 회사채(일반) | CU15: 46316 | CV15: KR6023531G64 | CW15: 023531 | CX15: 롯데쇼핑109-1 | CY15: 0 | CZ15: 2.36 | DA15: 0 | DB15: 2442697 | DC15: 10058.49 | DD15: 1.5625 | DE15: =_xll.IMDP("BND",CV15,DE8,CV3) -> 20280609 | DF15: =_xll.IMDP("BND",CV15,DF8,CV3) -> 4.453 | DG15: =_xll.IMDP("BND",CV15,DG8,CV3) -> 회사채 | DH15: =_xll.IMDP("BND",CV15,DH8,CV3) -> 회사채(일반) | DI15: 46316 | DJ15: KR6175333G96 | DK15: 175333 | DL15: JB금융지주45-3 | DM15: 0 | DN15: 0.91 | DO15: 0 | DP15: 1441428 | DQ15: 10067.58 | DR15: 1.8091 | DS15: =_xll.IMDP("BND",DJ15,DS8,DJ3) -> 20280915 | DT15: =_xll.IMDP("BND",DJ15,DT8,DJ3) -> 4.339 | DU15: =_xll.IMDP("BND",DJ15,DU8,DJ3) -> 회사채 | DV15: =_xll.IMDP("BND",DJ15,DV8,DJ3) -> 회사채(일반) | DW15: 46316 | DX15: KR601980BFC7 | DY15: 01980B | DZ15: 하나캐피탈470-5 | EA15: 0 | EB15: 4.88 | EC15: 0 | ED15: 5143473 | EE15: 9833.8 | EF15: 1.9837 | EG15: =_xll.IMDP("BND",DX15,EG8,DX3) -> 20281117 | EH15: =_xll.IMDP("BND",DX15,EH8,DX3) -> 4.412 | EI15: =_xll.IMDP("BND",DX15,EI8,DX3) -> 금융채 | EJ15: =_xll.IMDP("BND",DX15,EJ8,DX3) -> 기타금융채 | EK15: 46316 | EL15: KR357001GF94 | EM15: 57001G | EN15: 김해시도시개발공사2025-01(용두지구) | EO15: 0 | EP15: 2 | EQ15: 0 | ER15: 4566925 | ES15: 9746.01 | ET15: 1.8633 | EU15: =_xll.IMDP("BND",EL15,EU8,EL3) -> 20280926 | EV15: =_xll.IMDP("BND",EL15,EV8,EL3) -> 4.33 | EW15: =_xll.IMDP("BND",EL15,EW8,EL3) -> 공사공단채 | EX15: =_xll.IMDP("BND",EL15,EX8,EL3) -> 지방공기업
A16: 46316 | B16: KR103502GG95 | C16: 03502G | D16: 국고00000-5609(26-8) | E16: 0 | F16: 0.99 | G16: 0 | H16: 1186543 | I16: 10441.59 | J16: 16.5401 | K16: =_xll.IMDP("BND",B16,K8,B3) -> 20560910 | L16: =_xll.IMDP("BND",B16,L8,B3) -> 4.267 | M16: =_xll.IMDP("BND",B16,M8,B3) -> 국채 | N16: =_xll.IMDP("BND",B16,N8,B3) -> 국고채권 | O16: 46316 | P16: KR103503GG37 | Q16: 03503G | R16: 국고03375-3103(26-3) | S16: 0 | T16: 2.94 | U16: 0 | V16: 3995624 | W16: 9789.18 | X16: 4.0153 | Y16: =_xll.IMDP("BND",P16,Y8,P3) -> 20310310 | Z16: =_xll.IMDP("BND",P16,Z8,P3) -> 3.998 | AA16: =_xll.IMDP("BND",P16,AA8,P3) -> 국채 | AB16: =_xll.IMDP("BND",P16,AB8,P3) -> 국고채권 | AC16: 46316 | AD16: KR103502GC32 | AE16: 03502G | AF16: 국고02500-5203(22-2) | AG16: 0 | AH16: 5.61 | AI16: 0 | AJ16: 8094135 | AK16: 7236.69 | AL16: 17.144 | AM16: =_xll.IMDP("BND",AD16,AM8,AD3) -> 20520310 | AN16: =_xll.IMDP("BND",AD16,AN8,AD3) -> 4.321 | AO16: =_xll.IMDP("BND",AD16,AO8,AD3) -> 국채 | AP16: =_xll.IMDP("BND",AD16,AP8,AD3) -> 국고채권 | AQ16: 46316 | AR16: KR103502GC65 | AS16: 03502G | AT16: 국고03375-3206(22-5) | AU16: 0 | AV16: 0.48 | AW16: 0 | AX16: 492276 | AY16: 9820.45 | AZ16: 5.0103 | BA16: =_xll.IMDP("BND",AR16,BA8,AR3) -> 20320610 | BB16: =_xll.IMDP("BND",AR16,BB8,AR3) -> 3.977 | BC16: =_xll.IMDP("BND",AR16,BC8,AR3) -> 국채 | BD16: =_xll.IMDP("BND",AR16,BD8,AR3) -> 국고채권 | BE16: 46316 | BF16: - | BG16: - | BH16: 원화현금 | BJ16: 0.01 | BL16: 19918 | BO16: =_xll.IMDP("BND",BF16,BO8,BF3) | BP16: =_xll.IMDP("BND",BF16,BP8,BF3) | BQ16: =_xll.IMDP("BND",BF16,BQ8,BF3) | BR16: =_xll.IMDP("BND",BF16,BR8,BF3) | BS16: 46316 | BT16: KR103504GE95 | BU16: 03504G | BV16: 국고02875-4409(24-10) | BW16: 0 | BX16: 1.31 | BY16: 0 | BZ16: 1879873 | CA16: 8316.35 | CB16: 13.3243 | CC16: =_xll.IMDP("BND",BT16,CC8,BT3) -> 20440910 | CD16: =_xll.IMDP("BND",BT16,CD8,BT3) -> 4.254 | CE16: =_xll.IMDP("BND",BT16,CE8,BT3) -> 국채 | CF16: =_xll.IMDP("BND",BT16,CF8,BT3) -> 국고채권 | CG16: 46316 | CH16: KR6095922E20 | CI16: 095922 | CJ16: 현대커머셜507 | CK16: 0 | CL16: 1.59 | CM16: 0 | CN16: 2013221 | CO16: 10098.11 | CP16: 0.2886 | CQ16: =_xll.IMDP("BND",CH16,CQ8,CH3) -> 20270205 | CR16: =_xll.IMDP("BND",CH16,CR8,CH3) -> 3.678 | CS16: =_xll.IMDP("BND",CH16,CS8,CH3) -> 금융채 | CT16: =_xll.IMDP("BND",CH16,CT8,CH3) -> 기타금융채 | CU16: 46316 | CV16: KR6145766G87 | CW16: 145766 | CX16: BNK캐피탈394-1 | CY16: 0 | CZ16: 2.36 | DA16: 0 | DB16: 2441845 | DC16: 10055.78 | DD16: 2.569 | DE16: =_xll.IMDP("BND",CV16,DE8,CV3) -> 20290726 | DF16: =_xll.IMDP("BND",CV16,DF8,CV3) -> 4.549 | DG16: =_xll.IMDP("BND",CV16,DG8,CV3) -> 금융채 | DH16: =_xll.IMDP("BND",CV16,DH8,CV3) -> 기타금융채 | DI16: 46316 | DJ16: KR381101GG92 | DK16: 81101G | DL16: 농업금융채권(중앙회)2026-9이2Y-A | DM16: 0 | DN16: 0.91 | DO16: 0 | DP16: 1441186 | DQ16: 10065.93 | DR16: 1.8512 | DS16: =_xll.IMDP("BND",DJ16,DS8,DJ3) -> 20280930 | DT16: =_xll.IMDP("BND",DJ16,DT8,DJ3) -> 4.139 | DU16: =_xll.IMDP("BND",DJ16,DU8,DJ3) -> 공사공단채 | DV16: =_xll.IMDP("BND",DJ16,DV8,DJ3) -> 공사공단채 기타 | DW16: 46316 | DX16: KR6047811F73 | DY16: 047811 | DZ16: 한국항공우주산업29-1 | EA16: 0 | EB16: 4.85 | EC16: 0 | ED16: 5110188 | EE16: 9771 | EF16: 1.6502 | EG16: =_xll.IMDP("BND",DX16,EG8,DX3) -> 20280704 | EH16: =_xll.IMDP("BND",DX16,EH8,DX3) -> 4.293 | EI16: =_xll.IMDP("BND",DX16,EI8,DX3) -> 회사채 | EJ16: =_xll.IMDP("BND",DX16,EJ8,DX3) -> 회사채(일반) | EK16: 46316 | EL16: KR6003493F97 | EM16: 003493 | EN16: 대한항공112-3 | EO16: 0 | EP16: 1.53 | EQ16: 0 | ER16: 3502777 | ES16: 9343.21 | ET16: 5.2548 | EU16: =_xll.IMDP("BND",EL16,EU8,EL3) -> 20320930 | EV16: =_xll.IMDP("BND",EL16,EV8,EL3) -> 5.058 | EW16: =_xll.IMDP("BND",EL16,EW8,EL3) -> 회사채 | EX16: =_xll.IMDP("BND",EL16,EX8,EL3) -> 회사채(일반)
A17: 46316 | B17: KR4A676C0005 | C17: A676C000 | D17: 2026-12 국채선물10(신) | E17: 0 | F17: 0.88 | G17: 0.01 | H17: 1065700 | K17: =_xll.IMDP("BND",B17,K8,B3) | L17: =_xll.IMDP("BND",B17,L8,B3) | M17: =_xll.IMDP("BND",B17,M8,B3) | N17: =_xll.IMDP("BND",B17,N8,B3) | O17: 46316 | P17: KR103503GF38 | Q17: 03503G | R17: 국고02625-3003(25-3) | S17: 0 | T17: 2.89 | U17: 0 | V17: 3925922 | W17: 9618.51 | X17: 3.1881 | Y17: =_xll.IMDP("BND",P17,Y8,P3) -> 20300310 | Z17: =_xll.IMDP("BND",P17,Z8,P3) -> 3.932 | AA17: =_xll.IMDP("BND",P17,AA8,P3) -> 국채 | AB17: =_xll.IMDP("BND",P17,AB8,P3) -> 국고채권 | AC17: 46316 | AD17: KR103502GG95 | AE17: 03502G | AF17: 국고00000-5609(26-8) | AG17: 0 | AH17: 5 | AI17: 0 | AJ17: 7212939 | AK17: 10441.59 | AL17: 16.5401 | AM17: =_xll.IMDP("BND",AD17,AM8,AD3) -> 20560910 | AN17: =_xll.IMDP("BND",AD17,AN8,AD3) -> 4.267 | AO17: =_xll.IMDP("BND",AD17,AO8,AD3) -> 국채 | AP17: =_xll.IMDP("BND",AD17,AP8,AD3) -> 국고채권 | AQ17: 46316 | AR17: KR103502GEC4 | AS17: 03502G | AT17: 국고03000-3412(24-13) | AU17: 0 | AV17: 0.23 | AW17: 0 | AX17: 233816 | AY17: 9330.42 | AZ17: 7.0099 | BA17: =_xll.IMDP("BND",AR17,BA8,AR3) -> 20341210 | BB17: =_xll.IMDP("BND",AR17,BB8,AR3) -> 4.135 | BC17: =_xll.IMDP("BND",AR17,BC8,AR3) -> 국채 | BD17: =_xll.IMDP("BND",AR17,BD8,AR3) -> 국고채권 | BO17: =_xll.IMDP("BND",BF17,BO8,BF3) -> 입력오류 | BP17: =_xll.IMDP("BND",BF17,BP8,BF3) -> 입력오류 | BQ17: =_xll.IMDP("BND",BF17,BQ8,BF3) -> 입력오류 | BR17: =_xll.IMDP("BND",BF17,BR8,BF3) -> 입력오류 | BS17: 46316 | BT17: KR103502GE30 | BU17: 03502G | BV17: 국고03250-5403(24-2) | BW17: 0 | BX17: 1.28 | BY17: 0 | BZ17: 1832149 | CA17: 8346.45 | CB17: 16.9163 | CC17: =_xll.IMDP("BND",BT17,CC8,BT3) -> 20540310 | CD17: =_xll.IMDP("BND",BT17,CD8,BT3) -> 4.306 | CE17: =_xll.IMDP("BND",BT17,CE8,BT3) -> 국채 | CF17: =_xll.IMDP("BND",BT17,CF8,BT3) -> 국고채권 | CG17: 46316 | CH17: KR6003453E13 | CI17: 003453 | CJ17: KB증권43-3 | CK17: 0 | CL17: 1.59 | CM17: 0 | CN17: 2013035 | CO17: 10097.37 | CP17: 0.2698 | CQ17: =_xll.IMDP("BND",CH17,CQ8,CH3) -> 20270129 | CR17: =_xll.IMDP("BND",CH17,CR8,CH3) -> 3.669 | CS17: =_xll.IMDP("BND",CH17,CS8,CH3) -> 회사채 | CT17: =_xll.IMDP("BND",CH17,CT8,CH3) -> 회사채(일반) | CU17: 46316 | CV17: KR6008271GA6 | CW17: 008271 | CX17: 산은캐피탈795-1 | CY17: 0 | CZ17: 2.35 | DA17: 0 | DB17: 2436876 | DC17: 10034.52 | DD17: 1.8657 | DE17: =_xll.IMDP("BND",CV17,DE8,CV3) -> 20281006 | DF17: =_xll.IMDP("BND",CV17,DF8,CV3) -> 4.408 | DG17: =_xll.IMDP("BND",CV17,DG8,CV3) -> 금융채 | DH17: =_xll.IMDP("BND",CV17,DH8,CV3) -> 기타금융채 | DI17: 46316 | DJ17: KR6175332G30 | DK17: 175332 | DL17: JB금융지주40 | DM17: 0 | DN17: 0.9 | DO17: 0 | DP17: 1427035 | DQ17: 9966.95 | DR17: 0.9028 | DS17: =_xll.IMDP("BND",DJ17,DS8,DJ3) -> 20270923 | DT17: =_xll.IMDP("BND",DJ17,DT8,DJ3) -> 4.222 | DU17: =_xll.IMDP("BND",DJ17,DU8,DJ3) -> 회사채 | DV17: =_xll.IMDP("BND",DJ17,DV8,DJ3) -> 회사채(일반) | DW17: 46316 | DX17: KR6031321FA2 | DY17: 031321 | DZ17: 비씨카드184-1 | EA17: 0 | EB17: 4.85 | EC17: 0 | ED17: 5107782 | EE17: 9695.74 | EF17: 1.9165 | EG17: =_xll.IMDP("BND",DX17,EG8,DX3) -> 20281020 | EH17: =_xll.IMDP("BND",DX17,EH8,DX3) -> 4.398 | EI17: =_xll.IMDP("BND",DX17,EI8,DX3) -> 금융채 | EJ17: =_xll.IMDP("BND",DX17,EJ8,DX3) -> 카드 | EK17: 46316 | EL17: KR6018882E20 | EM17: 018882 | EN17: 한온시스템15-2 | EO17: 0 | EP17: 1.04 | EQ17: 0 | ER17: 2370897 | ES17: 10118.8 | ET17: 0.288 | EU17: =_xll.IMDP("BND",EL17,EU8,EL3) -> 20270205 | EV17: =_xll.IMDP("BND",EL17,EV8,EL3) -> 4.022 | EW17: =_xll.IMDP("BND",EL17,EW8,EL3) -> 회사채 | EX17: =_xll.IMDP("BND",EL17,EX8,EL3) -> 회사채(일반)
A18: 46316 | B18: KR310219GG82 | C18: 10219G | D18: 산금26신이0106-0828-2 | E18: 0 | F18: 0.84 | G18: 0 | H18: 1006538 | I18: 10038.42 | J18: 1.3067 | K18: =_xll.IMDP("BND",B18,K8,B3) -> 20280228 | L18: =_xll.IMDP("BND",B18,L8,B3) -> 3.986 | M18: =_xll.IMDP("BND",B18,M8,B3) -> 금융채 | N18: =_xll.IMDP("BND",B18,N8,B3) -> 은행채 | O18: 46316 | P18: KR103502GB33 | Q18: 03502G | R18: 국고01875-5103(21-2) | S18: 0 | T18: 2.71 | U18: 0 | V18: 3684554 | W18: 6402.24 | X18: 17.7604 | Y18: =_xll.IMDP("BND",P18,Y8,P3) -> 20510310 | Z18: =_xll.IMDP("BND",P18,Z8,P3) -> 4.28 | AA18: =_xll.IMDP("BND",P18,AA8,P3) -> 국채 | AB18: =_xll.IMDP("BND",P18,AB8,P3) -> 국고채권 | AC18: 46316 | AD18: KR103502GA34 | AE18: 03502G | AF18: 국고01500-5003(20-2) | AG18: 0 | AH18: 4.55 | AI18: 0 | AJ18: 6563770 | AK18: 5940.26 | AL18: 17.9913 | AM18: =_xll.IMDP("BND",AD18,AM8,AD3) -> 20500310 | AN18: =_xll.IMDP("BND",AD18,AN8,AD3) -> 4.274 | AO18: =_xll.IMDP("BND",AD18,AO8,AD3) -> 국채 | AP18: =_xll.IMDP("BND",AD18,AP8,AD3) -> 국고채권 | AQ18: 46316 | AR18: - | AS18: - | AT18: 원화현금 | AV18: 1.66 | AX18: 1721180 | BA18: =_xll.IMDP("BND",AR18,BA8,AR3) | BB18: =_xll.IMDP("BND",AR18,BB8,AR3) | BC18: =_xll.IMDP("BND",AR18,BC8,AR3) | BD18: =_xll.IMDP("BND",AR18,BD8,AR3) | BO18: =_xll.IMDP("BND",BF18,BO8,BF3) -> 입력오류 | BP18: =_xll.IMDP("BND",BF18,BP8,BF3) -> 입력오류 | BQ18: =_xll.IMDP("BND",BF18,BQ8,BF3) -> 입력오류 | BR18: =_xll.IMDP("BND",BF18,BR8,BF3) -> 입력오류 | BS18: 46316 | BT18: KR2005011E66 | BU18: 005011 | BV18: 광주광역시지방채2024-01 | BW18: 0 | BX18: 1.22 | BY18: 0 | BZ18: 1741546 | CA18: 10130.69 | CB18: 0.5986 | CC18: =_xll.IMDP("BND",BT18,CC8,BT3) -> 20270604 | CD18: =_xll.IMDP("BND",BT18,CD8,BT3) -> 3.579 | CE18: =_xll.IMDP("BND",BT18,CE8,BT3) -> 지방채 | CF18: =_xll.IMDP("BND",BT18,CF8,BT3) -> 공모지방채 | CG18: 46316 | CH18: KR6021241E20 | CI18: 021241 | CJ18: 코웨이6-1 | CK18: 0 | CL18: 1.58 | CM18: 0 | CN18: 2007677 | CO18: 10070.32 | CP18: 0.3331 | CQ18: =_xll.IMDP("BND",CH18,CQ8,CH3) -> 20270222 | CR18: =_xll.IMDP("BND",CH18,CR8,CH3) -> 3.853 | CS18: =_xll.IMDP("BND",CH18,CS8,CH3) -> 회사채 | CT18: =_xll.IMDP("BND",CH18,CT8,CH3) -> 회사채(일반) | CU18: 46316 | CV18: KR6046293G14 | CW18: 046293 | CX18: 엠지캐피탈394-3 | CY18: 0 | CZ18: 2.35 | DA18: 0 | DB18: 2429754 | DC18: 10005 | DD18: 0.739 | DE18: =_xll.IMDP("BND",CV18,DE8,CV3) -> 20270726 | DF18: =_xll.IMDP("BND",CV18,DF8,CV3) -> 5.291 | DG18: =_xll.IMDP("BND",CV18,DG8,CV3) -> 금융채 | DH18: =_xll.IMDP("BND",CV18,DH8,CV3) -> 기타금융채 | DI18: 46316 | DJ18: KRZE03201G7V | DK18: E03201 | DL18: 부산 금융시장지원부 20260728-184-1 | DM18: 0 | DN18: 0.9 | DO18: 0 | DP18: 1418846 | DS18: =_xll.IMDP("BND",DJ18,DS8,DJ3) | DT18: =_xll.IMDP("BND",DJ18,DT8,DJ3) | DU18: =_xll.IMDP("BND",DJ18,DU8,DJ3) | DV18: =_xll.IMDP("BND",DJ18,DV8,DJ3) | DW18: 46316 | DX18: KR6097248F97 | DY18: 097248 | DZ18: 엔에이치농협캐피탈252-8 | EA18: 0 | EB18: 4.83 | EC18: 0 | ED18: 5086579 | EE18: 9725.8 | EF18: 1.8606 | EG18: =_xll.IMDP("BND",DX18,EG8,DX3) -> 20280925 | EH18: =_xll.IMDP("BND",DX18,EH8,DX3) -> 4.417 | EI18: =_xll.IMDP("BND",DX18,EI8,DX3) -> 금융채 | EJ18: =_xll.IMDP("BND",DX18,EJ8,DX3) -> 기타금융채 | EK18: 46316 | EL18: KR6169374F25 | EM18: 169374 | EN18: 메리츠캐피탈271-4 | EO18: 0 | EP18: 1.03 | EQ18: 0 | ER18: 2357038 | ES18: 10059.49 | ET18: 0.3749 | EU18: =_xll.IMDP("BND",EL18,EU8,EL3) -> 20270310 | EV18: =_xll.IMDP("BND",EL18,EV8,EL3) -> 4.291 | EW18: =_xll.IMDP("BND",EL18,EW8,EL3) -> 금융채 | EX18: =_xll.IMDP("BND",EL18,EX8,EL3) -> 기타금융채
A19: 46316 | B19: KR6373224E26 | C19: 373224 | D19: LG에너지솔루션3-4(녹) | E19: 0 | F19: 0.83 | G19: 0 | H19: 998939 | I19: 9962.57 | J19: 3.9001 | K19: =_xll.IMDP("BND",B19,K8,B3) -> 20310216 | L19: =_xll.IMDP("BND",B19,L8,B3) -> 4.49 | M19: =_xll.IMDP("BND",B19,M8,B3) -> 회사채 | N19: =_xll.IMDP("BND",B19,N8,B3) -> 회사채(일반) | O19: 46316 | P19: KR356103GD46 | Q19: 56103G | R19: 토지주택채권430 | S19: 0 | T19: 2.2 | U19: 0 | V19: 2983421 | W19: 9132.13 | X19: 12.1019 | Y19: =_xll.IMDP("BND",P19,Y8,P3) -> 20430420 | Z19: =_xll.IMDP("BND",P19,Z8,P3) -> 4.402 | AA19: =_xll.IMDP("BND",P19,AA8,P3) -> 공사공단채 | AB19: =_xll.IMDP("BND",P19,AB8,P3) -> 일반 | AC19: 46316 | AD19: KR103501GG39 | AE19: 03501G | AF19: 국고03500-5603(26-2) | AG19: 0 | AH19: 3.58 | AI19: 0 | AJ19: 5169664 | AK19: 8730.99 | AL19: 17.2848 | AM19: =_xll.IMDP("BND",AD19,AM8,AD3) -> 20560310 | AN19: =_xll.IMDP("BND",AD19,AN8,AD3) -> 4.287 | AO19: =_xll.IMDP("BND",AD19,AO8,AD3) -> 국채 | AP19: =_xll.IMDP("BND",AD19,AP8,AD3) -> 국고채권 | BA19: =_xll.IMDP("BND",AR19,BA8,AR3) -> 입력오류 | BB19: =_xll.IMDP("BND",AR19,BB8,AR3) -> 입력오류 | BC19: =_xll.IMDP("BND",AR19,BC8,AR3) -> 입력오류 | BD19: =_xll.IMDP("BND",AR19,BD8,AR3) -> 입력오류 | BO19: =_xll.IMDP("BND",BF19,BO8,BF3) -> 입력오류 | BP19: =_xll.IMDP("BND",BF19,BP8,BF3) -> 입력오류 | BQ19: =_xll.IMDP("BND",BF19,BQ8,BF3) -> 입력오류 | BR19: =_xll.IMDP("BND",BF19,BR8,BF3) -> 입력오류 | BS19: 46316 | BT19: KR6105562G53 | BU19: 105562 | BV19: KB금융지주61-1 | BW19: 0 | BX19: 1.2 | BY19: 0 | BZ19: 1722899 | CA19: 10020.97 | CB19: 2.4372 | CC19: =_xll.IMDP("BND",BT19,CC8,BT3) -> 20290526 | CD19: =_xll.IMDP("BND",BT19,CD8,BT3) -> 4.259 | CE19: =_xll.IMDP("BND",BT19,CE8,BT3) -> 회사채 | CF19: =_xll.IMDP("BND",BT19,CF8,BT3) -> 회사채(일반) | CG19: 46316 | CH19: KR6169374EB6 | CI19: 169374 | CJ19: 메리츠캐피탈267-1 | CK19: 0 | CL19: 1.58 | CM19: 0 | CN19: 2006062 | CO19: 10062.24 | CP19: 0.1013 | CQ19: =_xll.IMDP("BND",CH19,CQ8,CH3) -> 20261127 | CR19: =_xll.IMDP("BND",CH19,CR8,CH3) -> 3.905 | CS19: =_xll.IMDP("BND",CH19,CS8,CH3) -> 금융채 | CT19: =_xll.IMDP("BND",CH19,CT8,CH3) -> 기타금융채 | CU19: 46316 | CV19: KR6003342G73 | CW19: 003342 | CX19: SK에코플랜트186-2 | CY19: 0 | CZ19: 2.34 | DA19: 0 | DB19: 2428389 | DC19: 9999.42 | DD19: 1.232 | DE19: =_xll.IMDP("BND",CV19,DE8,CV3) -> 20280130 | DF19: =_xll.IMDP("BND",CV19,DF8,CV3) -> 5.041 | DG19: =_xll.IMDP("BND",CV19,DG8,CV3) -> 회사채 | DH19: =_xll.IMDP("BND",CV19,DH8,CV3) -> 회사채(일반) | DI19: 46316 | DJ19: KR103504GC97 | DK19: 03504G | DL19: 국고채권03250-4209(22-11) | DM19: 0 | DN19: 0.82 | DO19: 0 | DP19: 1291619 | DQ19: 8867.54 | DR19: 11.9722 | DS19: =_xll.IMDP("BND",DJ19,DS8,DJ3) -> 20420910 | DT19: =_xll.IMDP("BND",DJ19,DT8,DJ3) -> 4.27 | DU19: =_xll.IMDP("BND",DJ19,DU8,DJ3) -> 국채 | DV19: =_xll.IMDP("BND",DJ19,DV8,DJ3) -> 국고채권 | DW19: 46316 | DX19: KR6004948G95 | DY19: 004948 | DZ19: 하나은행49-09이3갑-17 | EA19: 0 | EB19: 4.02 | EC19: 0 | ED19: 4233643 | EE19: 10119.34 | EF19: 2.7038 | EG19: =_xll.IMDP("BND",DX19,EG8,DX3) -> 20290917 | EH19: =_xll.IMDP("BND",DX19,EH8,DX3) -> 4.215 | EI19: =_xll.IMDP("BND",DX19,EI8,DX3) -> 금융채 | EJ19: =_xll.IMDP("BND",DX19,EJ8,DX3) -> 은행채 | EK19: 46316 | EL19: KR6086791G90 | EM19: 086791 | EN19: 하나금융지주75 | EO19: 0 | EP19: 1.03 | EQ19: 0 | ER19: 2356443 | ES19: 10055.76 | ET19: 2.6936 | EU19: =_xll.IMDP("BND",EL19,EU8,EL3) -> 20290911 | EV19: =_xll.IMDP("BND",EL19,EV8,EL3) -> 4.272 | EW19: =_xll.IMDP("BND",EL19,EW8,EL3) -> 회사채 | EX19: =_xll.IMDP("BND",EL19,EX8,EL3) -> 회사채(일반)
A20: 46316 | B20: KR103502GA34 | C20: 03502G | D20: 국고01500-5003(20-2) | E20: 0 | F20: 0.83 | G20: 0 | H20: 995200 | I20: 5940.26 | J20: 17.9913 | K20: =_xll.IMDP("BND",B20,K8,B3) -> 20500310 | L20: =_xll.IMDP("BND",B20,L8,B3) -> 4.274 | M20: =_xll.IMDP("BND",B20,M8,B3) -> 국채 | N20: =_xll.IMDP("BND",B20,N8,B3) -> 국고채권 | O20: 46316 | P20: KR103501GG39 | Q20: 03501G | R20: 국고03500-5603(26-2) | S20: 0 | T20: 2.1 | U20: 0 | V20: 2850935 | W20: 8730.99 | X20: 17.2848 | Y20: =_xll.IMDP("BND",P20,Y8,P3) -> 20560310 | Z20: =_xll.IMDP("BND",P20,Z8,P3) -> 4.287 | AA20: =_xll.IMDP("BND",P20,AA8,P3) -> 국채 | AB20: =_xll.IMDP("BND",P20,AB8,P3) -> 국고채권 | AC20: 46316 | AD20: KR103504GE95 | AE20: 03504G | AF20: 국고02875-4409(24-10) | AG20: 0 | AH20: 3.41 | AI20: 0 | AJ20: 4924100 | AK20: 8316.35 | AL20: 13.3243 | AM20: =_xll.IMDP("BND",AD20,AM8,AD3) -> 20440910 | AN20: =_xll.IMDP("BND",AD20,AN8,AD3) -> 4.254 | AO20: =_xll.IMDP("BND",AD20,AO8,AD3) -> 국채 | AP20: =_xll.IMDP("BND",AD20,AP8,AD3) -> 국고채권 | BA20: =_xll.IMDP("BND",AR20,BA8,AR3) -> 입력오류 | BB20: =_xll.IMDP("BND",AR20,BB8,AR3) -> 입력오류 | BC20: =_xll.IMDP("BND",AR20,BC8,AR3) -> 입력오류 | BD20: =_xll.IMDP("BND",AR20,BD8,AR3) -> 입력오류 | BO20: =_xll.IMDP("BND",BF20,BO8,BF3) -> 입력오류 | BP20: =_xll.IMDP("BND",BF20,BP8,BF3) -> 입력오류 | BQ20: =_xll.IMDP("BND",BF20,BQ8,BF3) -> 입력오류 | BR20: =_xll.IMDP("BND",BF20,BR8,BF3) -> 입력오류 | BS20: 46316 | BT20: KR103503GG37 | BU20: 03503G | BV20: 국고03375-3103(26-3) | BW20: 0 | BX20: 0.98 | BY20: 0 | BZ20: 1398167 | CA20: 9789.18 | CB20: 4.0153 | CC20: =_xll.IMDP("BND",BT20,CC8,BT3) -> 20310310 | CD20: =_xll.IMDP("BND",BT20,CD8,BT3) -> 3.998 | CE20: =_xll.IMDP("BND",BT20,CE8,BT3) -> 국채 | CF20: =_xll.IMDP("BND",BT20,CF8,BT3) -> 국고채권 | CG20: 46316 | CH20: KR6089862C19 | CI20: 089862 | CJ20: 롯데렌탈56-2(녹) | CK20: 0 | CL20: 1.58 | CM20: 0 | CN20: 2004525 | CO20: 10054.61 | CP20: 0.2608 | CQ20: =_xll.IMDP("BND",CH20,CQ8,CH3) -> 20270126 | CR20: =_xll.IMDP("BND",CH20,CR8,CH3) -> 3.846 | CS20: =_xll.IMDP("BND",CH20,CS8,CH3) -> 회사채 | CT20: =_xll.IMDP("BND",CH20,CT8,CH3) -> 회사채(일반) | CU20: 46316 | CV20: KR6023763F49 | CW20: 023763 | CX20: 한국캐피탈545-3 | CY20: 0 | CZ20: 2.34 | DA20: 0 | DB20: 2423049 | DC20: 9977.86 | DD20: 0.4575 | DE20: =_xll.IMDP("BND",CV20,DE8,CV3) -> 20270409 | DF20: =_xll.IMDP("BND",CV20,DF8,CV3) -> 4.826 | DG20: =_xll.IMDP("BND",CV20,DG8,CV3) -> 금융채 | DH20: =_xll.IMDP("BND",CV20,DH8,CV3) -> 기타금융채 | DI20: 46316 | DJ20: KR103502GE63 | DK20: 03502G | DL20: 국고채권03500-3406(24-5) | DM20: 0 | DN20: 0.79 | DO20: 0 | DP20: 1247180 | DQ20: 9726.04 | DR20: 6.5257 | DS20: =_xll.IMDP("BND",DJ20,DS8,DJ3) -> 20340610 | DT20: =_xll.IMDP("BND",DJ20,DT8,DJ3) -> 4.116 | DU20: =_xll.IMDP("BND",DJ20,DU8,DJ3) -> 국채 | DV20: =_xll.IMDP("BND",DJ20,DV8,DJ3) -> 국고채권 | DW20: 46316 | DX20: KR103503GG94 | DY20: 03503G | DZ20: 국고00000-3109(26-9) | EA20: 0 | EB20: 4.01 | EC20: 0 | ED20: 4229133 | EE20: 10107.63 | EF20: 4.3722 | EG20: =_xll.IMDP("BND",DX20,EG8,DX3) -> 20310910 | EH20: =_xll.IMDP("BND",DX20,EH8,DX3) -> 3.985 | EI20: =_xll.IMDP("BND",DX20,EI8,DX3) -> 국채 | EJ20: =_xll.IMDP("BND",DX20,EJ8,DX3) -> 국고채권 | EK20: 46316 | EL20: KR6008272G92 | EM20: 008272 | EN20: 산은캐피탈794-2 | EO20: 0 | EP20: 1.03 | EQ20: 0 | ER20: 2356394 | ES20: 10056.32 | ET20: 2.0326 | EU20: =_xll.IMDP("BND",EL20,EU8,EL3) -> 20281215 | EV20: =_xll.IMDP("BND",EL20,EV8,EL3) -> 4.429 | EW20: =_xll.IMDP("BND",EL20,EW8,EL3) -> 금융채 | EX20: =_xll.IMDP("BND",EL20,EX8,EL3) -> 기타금융채
A21: 46316 | B21: KRC0350C3098 | C21: 0350C3 | D21: 국고채이자01870-3009 | E21: 0 | F21: 0.71 | G21: 0 | H21: 860484 | I21: 8581.91 | J21: 3.7395 | K21: =_xll.IMDP("BND",B21,K8,B3) -> 20300910 | L21: =_xll.IMDP("BND",B21,L8,B3) -> 4.01 | M21: =_xll.IMDP("BND",B21,M8,B3) -> 국채 | N21: =_xll.IMDP("BND",B21,N8,B3) -> 국고채권 | O21: 46316 | P21: KR103502GE63 | Q21: 03502G | R21: 국고채권03500-3406(24-5) | S21: 0 | T21: 2.05 | U21: 0 | V21: 2778837 | W21: 9726.04 | X21: 6.5257 | Y21: =_xll.IMDP("BND",P21,Y8,P3) -> 20340610 | Z21: =_xll.IMDP("BND",P21,Z8,P3) -> 4.116 | AA21: =_xll.IMDP("BND",P21,AA8,P3) -> 국채 | AB21: =_xll.IMDP("BND",P21,AB8,P3) -> 국고채권 | AC21: 46316 | AD21: KR103502GD98 | AE21: 03502G | AF21: 국고03625-5309(23-7) | AG21: 0 | AH21: 3.06 | AI21: 0 | AJ21: 4421081 | AK21: 8958.96 | AL21: 16.3566 | AM21: =_xll.IMDP("BND",AD21,AM8,AD3) -> 20530910 | AN21: =_xll.IMDP("BND",AD21,AN8,AD3) -> 4.308 | AO21: =_xll.IMDP("BND",AD21,AO8,AD3) -> 국채 | AP21: =_xll.IMDP("BND",AD21,AP8,AD3) -> 국고채권 | BA21: =_xll.IMDP("BND",AR21,BA8,AR3) -> 입력오류 | BB21: =_xll.IMDP("BND",AR21,BB8,AR3) -> 입력오류 | BC21: =_xll.IMDP("BND",AR21,BC8,AR3) -> 입력오류 | BD21: =_xll.IMDP("BND",AR21,BD8,AR3) -> 입력오류 | BO21: =_xll.IMDP("BND",BF21,BO8,BF3) -> 입력오류 | BP21: =_xll.IMDP("BND",BF21,BP8,BF3) -> 입력오류 | BQ21: =_xll.IMDP("BND",BF21,BQ8,BF3) -> 입력오류 | BR21: =_xll.IMDP("BND",BF21,BR8,BF3) -> 입력오류 | BS21: 46316 | BT21: KR103502GFC1 | BU21: 03502G | BV21: 국고03250-3512(25-11) | BW21: 0 | BX21: 0.91 | BY21: 0 | BZ21: 1296942 | CA21: 9424.3 | CB21: 7.67 | CC21: =_xll.IMDP("BND",BT21,CC8,BT3) -> 20351210 | CD21: =_xll.IMDP("BND",BT21,CD8,BT3) -> 4.17 | CE21: =_xll.IMDP("BND",BT21,CE8,BT3) -> 국채 | CF21: =_xll.IMDP("BND",BT21,CF8,BT3) -> 국고채권 | CG21: 46316 | CH21: KR6036321E13 | CI21: 036321 | CJ21: 미래에셋자산운용9 | CK21: 0 | CL21: 1.58 | CM21: 0 | CN21: 1996805 | CO21: 10016 | CP21: 0.233 | CQ21: =_xll.IMDP("BND",CH21,CQ8,CH3) -> 20270115 | CR21: =_xll.IMDP("BND",CH21,CR8,CH3) -> 3.75 | CS21: =_xll.IMDP("BND",CH21,CS8,CH3) -> 회사채 | CT21: =_xll.IMDP("BND",CH21,CT8,CH3) -> 회사채(일반) | CU21: 46316 | CV21: KR6046294FB2 | CW21: 046294 | CX21: 엠지캐피탈390-4 | CY21: 0 | CZ21: 2.34 | DA21: 0 | DB21: 2420929 | DC21: 9968.98 | DD21: 1.0411 | DE21: =_xll.IMDP("BND",CV21,DE8,CV3) -> 20271119 | DF21: =_xll.IMDP("BND",CV21,DF8,CV3) -> 5.282 | DG21: =_xll.IMDP("BND",CV21,DG8,CV3) -> 금융채 | DH21: =_xll.IMDP("BND",CV21,DH8,CV3) -> 기타금융채 | DI21: 46316 | DJ21: KR6205491F66 | DK21: 205491 | DL21: 하나카드281-1 | DM21: 0 | DN21: 0.74 | DO21: 0 | DP21: 1175496 | DQ21: 9852.73 | DR21: 1.1906 | DS21: =_xll.IMDP("BND",DJ21,DS8,DJ3) -> 20280110 | DT21: =_xll.IMDP("BND",DJ21,DT8,DJ3) -> 4.225 | DU21: =_xll.IMDP("BND",DJ21,DU8,DJ3) -> 금융채 | DV21: =_xll.IMDP("BND",DJ21,DV8,DJ3) -> 카드 | DW21: 46316 | DX21: KR4A656C0009 | DY21: A656C000 | DZ21: 2026-12 국채선물3(신) | EA21: 0 | EB21: 3.91 | EC21: -0.04 | ED21: -4122400 | EG21: =_xll.IMDP("BND",DX21,EG8,DX3) | EH21: =_xll.IMDP("BND",DX21,EH8,DX3) | EI21: =_xll.IMDP("BND",DX21,EI8,DX3) | EJ21: =_xll.IMDP("BND",DX21,EJ8,DX3) | EK21: 46316 | EL21: KR6169375F24 | EM21: 169375 | EN21: 메리츠캐피탈271-5 | EO21: 0 | EP21: 1.03 | EQ21: 0 | ER21: 2346455 | ES21: 10014.33 | ET21: 0.7808 | EU21: =_xll.IMDP("BND",EL21,EU8,EL3) -> 20270810 | EV21: =_xll.IMDP("BND",EL21,EV8,EL3) -> 4.747 | EW21: =_xll.IMDP("BND",EL21,EW8,EL3) -> 금융채 | EX21: =_xll.IMDP("BND",EL21,EX8,EL3) -> 기타금융채
A22: 46316 | B22: KR103502G933 | C22: 03502G | D22: 국고02000-4903(19-2) | E22: 0 | F22: 0.71 | G22: 0 | H22: 858150 | I22: 6719.49 | J22: 16.5686 | K22: =_xll.IMDP("BND",B22,K8,B3) -> 20490310 | L22: =_xll.IMDP("BND",B22,L8,B3) -> 4.315 | M22: =_xll.IMDP("BND",B22,M8,B3) -> 국채 | N22: =_xll.IMDP("BND",B22,N8,B3) -> 국고채권 | O22: 46316 | P22: KR103502GC99 | Q22: 03502G | R22: 국고03125-5209(22-9) | S22: 0 | T22: 1.97 | U22: 0 | V22: 2672378 | W22: 8183.03 | X22: 16.5318 | Y22: =_xll.IMDP("BND",P22,Y8,P3) -> 20520910 | Z22: =_xll.IMDP("BND",P22,Z8,P3) -> 4.32 | AA22: =_xll.IMDP("BND",P22,AA8,P3) -> 국채 | AB22: =_xll.IMDP("BND",P22,AB8,P3) -> 국고채권 | AC22: 46316 | AD22: KR103504GC97 | AE22: 03504G | AF22: 국고03250-4209(22-11) | AG22: 0 | AH22: 2.43 | AI22: 0 | AJ22: 3500415 | AK22: 8867.54 | AL22: 11.9722 | AM22: =_xll.IMDP("BND",AD22,AM8,AD3) -> 20420910 | AN22: =_xll.IMDP("BND",AD22,AN8,AD3) -> 4.27 | AO22: =_xll.IMDP("BND",AD22,AO8,AD3) -> 국채 | AP22: =_xll.IMDP("BND",AD22,AP8,AD3) -> 국고채권 | BA22: =_xll.IMDP("BND",AR22,BA8,AR3) -> 입력오류 | BB22: =_xll.IMDP("BND",AR22,BB8,AR3) -> 입력오류 | BC22: =_xll.IMDP("BND",AR22,BC8,AR3) -> 입력오류 | BD22: =_xll.IMDP("BND",AR22,BD8,AR3) -> 입력오류 | BO22: =_xll.IMDP("BND",BF22,BO8,BF3) -> 입력오류 | BP22: =_xll.IMDP("BND",BF22,BP8,BF3) -> 입력오류 | BQ22: =_xll.IMDP("BND",BF22,BQ8,BF3) -> 입력오류 | BR22: =_xll.IMDP("BND",BF22,BR8,BF3) -> 입력오류 | BS22: 46316 | BT22: KR353603GG11 | BU22: 53603G | BV22: 경기주택도시공사26-01-128 | BW22: 0 | BX22: 0.9 | BY22: 0 | BZ22: 1285695 | CA22: 9971.14 | CB22: 1.2034 | CC22: =_xll.IMDP("BND",BT22,CC8,BT3) -> 20280121 | CD22: =_xll.IMDP("BND",BT22,CD8,BT3) -> 4.083 | CE22: =_xll.IMDP("BND",BT22,CE8,BT3) -> 공사공단채 | CF22: =_xll.IMDP("BND",BT22,CF8,BT3) -> 지방공기업 | CG22: 46316 | CH22: KRZS42059159 | CI22: S42059 | CJ22: 키움에프앤아이 20260819-91-7(단) | CK22: 0 | CL22: 1.57 | CM22: 0 | CN22: 1987979 | CQ22: =_xll.IMDP("BND",CH22,CQ8,CH3) | CR22: =_xll.IMDP("BND",CH22,CR8,CH3) | CS22: =_xll.IMDP("BND",CH22,CS8,CH3) | CT22: =_xll.IMDP("BND",CH22,CT8,CH3) | CU22: 46316 | CV22: KR6375502E73 | CW22: 375502 | CX22: DL이앤씨2-2 | CY22: 0 | CZ22: 2.34 | DA22: 0 | DB22: 2420167 | DC22: 9965.41 | DD22: 0.7032 | DE22: =_xll.IMDP("BND",CV22,DE8,CV3) -> 20270709 | DF22: =_xll.IMDP("BND",CV22,DF8,CV3) -> 4.306 | DG22: =_xll.IMDP("BND",CV22,DG8,CV3) -> 회사채 | DH22: =_xll.IMDP("BND",CV22,DH8,CV3) -> 회사채(일반) | DI22: 46316 | DJ22: KR103502GE97 | DK22: 03502G | DL22: 국고채권02750-5409(24-8) | DM22: 0 | DN22: 0.67 | DO22: 0 | DP22: 1057292 | DQ22: 7534.48 | DR22: 17.7308 | DS22: =_xll.IMDP("BND",DJ22,DS8,DJ3) -> 20540910 | DT22: =_xll.IMDP("BND",DJ22,DT8,DJ3) -> 4.294 | DU22: =_xll.IMDP("BND",DJ22,DU8,DJ3) -> 국채 | DV22: =_xll.IMDP("BND",DJ22,DV8,DJ3) -> 국고채권 | DW22: 46316 | DX22: KR601945AG73 | DY22: 01945A | DZ22: 아이비케이캐피탈357-2 | EA22: 0 | EB22: 3.01 | EC22: 0 | ED22: 3174018 | EE22: 10114.25 | EF22: 1.7435 | EG22: =_xll.IMDP("BND",DX22,EG8,DX3) -> 20280824 | EH22: =_xll.IMDP("BND",DX22,EH8,DX3) -> 4.358 | EI22: =_xll.IMDP("BND",DX22,EI8,DX3) -> 금융채 | EJ22: =_xll.IMDP("BND",DX22,EJ8,DX3) -> 기타금융채 | EK22: 46316 | EL22: KR6139132C32 | EM22: 139132 | EN22: iM금융지주19 | EO22: 0 | EP22: 1.02 | EQ22: 0 | ER22: 2344465 | ES22: 10005.87 | ET22: 0.4354 | EU22: =_xll.IMDP("BND",EL22,EU8,EL3) -> 20270330 | EV22: =_xll.IMDP("BND",EL22,EV8,EL3) -> 3.901 | EW22: =_xll.IMDP("BND",EL22,EW8,EL3) -> 회사채 | EX22: =_xll.IMDP("BND",EL22,EX8,EL3) -> 회사채(일반)
A23: 46316 | B23: KR103502G891 | C23: 03502G | D23: 국고02375-3809(18-7) | E23: 0 | F23: 0.7 | G23: 0 | H23: 842038 | I23: 8342.88 | J23: 10.0095 | K23: =_xll.IMDP("BND",B23,K8,B3) -> 20380910 | L23: =_xll.IMDP("BND",B23,L8,B3) -> 4.187 | M23: =_xll.IMDP("BND",B23,M8,B3) -> 국채 | N23: =_xll.IMDP("BND",B23,N8,B3) -> 국고채권 | O23: 46316 | P23: KR103502GD98 | Q23: 03502G | R23: 국고03625-5309(23-7) | S23: 0 | T23: 1.89 | U23: 0 | V23: 2560017 | W23: 8958.96 | X23: 16.3566 | Y23: =_xll.IMDP("BND",P23,Y8,P3) -> 20530910 | Z23: =_xll.IMDP("BND",P23,Z8,P3) -> 4.308 | AA23: =_xll.IMDP("BND",P23,AA8,P3) -> 국채 | AB23: =_xll.IMDP("BND",P23,AB8,P3) -> 국고채권 | AC23: 46316 | AD23: KR103502GB33 | AE23: 03502G | AF23: 국고01875-5103(21-2) | AG23: 0 | AH23: 2.19 | AI23: 0 | AJ23: 3158999 | AK23: 6402.24 | AL23: 17.7604 | AM23: =_xll.IMDP("BND",AD23,AM8,AD3) -> 20510310 | AN23: =_xll.IMDP("BND",AD23,AN8,AD3) -> 4.28 | AO23: =_xll.IMDP("BND",AD23,AO8,AD3) -> 국채 | AP23: =_xll.IMDP("BND",AD23,AP8,AD3) -> 국고채권 | BA23: =_xll.IMDP("BND",AR23,BA8,AR3) -> 입력오류 | BB23: =_xll.IMDP("BND",AR23,BB8,AR3) -> 입력오류 | BC23: =_xll.IMDP("BND",AR23,BC8,AR3) -> 입력오류 | BD23: =_xll.IMDP("BND",AR23,BD8,AR3) -> 입력오류 | BO23: =_xll.IMDP("BND",BF23,BO8,BF3) -> 입력오류 | BP23: =_xll.IMDP("BND",BF23,BP8,BF3) -> 입력오류 | BQ23: =_xll.IMDP("BND",BF23,BQ8,BF3) -> 입력오류 | BR23: =_xll.IMDP("BND",BF23,BR8,BF3) -> 입력오류 | BS23: 46316 | BT23: KR1035027WC3 | BU23: 035027 | BV23: 국고05500-2912(09-5) | BW23: 0 | BX23: 0.84 | BY23: 0 | BZ23: 1201192 | CA23: 10667.13 | CB23: 2.8225 | CC23: =_xll.IMDP("BND",BT23,CC8,BT3) -> 20291210 | CD23: =_xll.IMDP("BND",BT23,CD8,BT3) -> 3.899 | CE23: =_xll.IMDP("BND",BT23,CE8,BT3) -> 국채 | CF23: =_xll.IMDP("BND",BT23,CF8,BT3) -> 국고채권 | CG23: 46316 | CH23: KRZS08986021 | CI23: S08986 | CJ23: 롯데렌탈 20260921-60-3(단) | CK23: 0 | CL23: 1.34 | CM23: 0 | CN23: 1699015 | CQ23: =_xll.IMDP("BND",CH23,CQ8,CH3) | CR23: =_xll.IMDP("BND",CH23,CR8,CH3) | CS23: =_xll.IMDP("BND",CH23,CS8,CH3) | CT23: =_xll.IMDP("BND",CH23,CT8,CH3) | CU23: 46316 | CV23: KR6021963G40 | CW23: 021963 | CX23: 케이비캐피탈580-3 | CY23: 0 | CZ23: 2.34 | DA23: 0 | DB23: 2419773 | DC23: 9964.51 | DD23: 1.4195 | DE23: =_xll.IMDP("BND",CV23,DE8,CV3) -> 20280410 | DF23: =_xll.IMDP("BND",CV23,DF8,CV3) -> 4.272 | DG23: =_xll.IMDP("BND",CV23,DG8,CV3) -> 금융채 | DH23: =_xll.IMDP("BND",CV23,DH8,CV3) -> 기타금융채 | DI23: 46316 | DJ23: KR103503GF38 | DK23: 03503G | DL23: 국고채권02625-3003(25-3) | DM23: 0 | DN23: 0.64 | DO23: 0 | DP23: 1009865 | DQ23: 9618.51 | DR23: 3.1881 | DS23: =_xll.IMDP("BND",DJ23,DS8,DJ3) -> 20300310 | DT23: =_xll.IMDP("BND",DJ23,DT8,DJ3) -> 3.932 | DU23: =_xll.IMDP("BND",DJ23,DU8,DJ3) -> 국채 | DV23: =_xll.IMDP("BND",DJ23,DV8,DJ3) -> 국고채권 | DW23: 46316 | DX23: KR6019458G87 | DY23: 019458 | DZ23: 아이비케이캐피탈359-3(녹) | EA23: 0 | EB23: 3 | EC23: 0 | ED23: 3155974 | EE23: 10056.02 | EF23: 2.6424 | EG23: =_xll.IMDP("BND",DX23,EG8,DX3) -> 20290824 | EH23: =_xll.IMDP("BND",DX23,EH8,DX3) -> 4.451 | EI23: =_xll.IMDP("BND",DX23,EI8,DX3) -> 금융채 | EJ23: =_xll.IMDP("BND",DX23,EJ8,DX3) -> 기타금융채 | EK23: 46316 | EL23: KR6169372F43 | EM23: 169372 | EN23: 메리츠캐피탈276-2 | EO23: 0 | EP23: 1.02 | EQ23: 0 | ER23: 2343345 | ES23: 10001.19 | ET23: 0.2221 | EU23: =_xll.IMDP("BND",EL23,EU8,EL3) -> 20270111 | EV23: =_xll.IMDP("BND",EL23,EV8,EL3) -> 3.978 | EW23: =_xll.IMDP("BND",EL23,EW8,EL3) -> 금융채 | EX23: =_xll.IMDP("BND",EL23,EX8,EL3) -> 기타금융채
